<?xml version='1.0' encoding='utf-8'?>
<robot name="generated_multileg">
  <link name="base_link">
    <inertial>
      <origin xyz="0.003201805 0.000883913 0.000000000" rpy="0 0 0" />
      <mass value="43.018476929" />
      <inertia ixx="0.775781723" ixy="0.022784148" ixz="0.000000000" iyy="1.878961933" iyz="0.000000000" izz="2.422443880" />
    </inertial>
    <visual>
      <origin xyz="0 0 0" rpy="0 0 0" />
      <geometry>
        <mesh filename="meshes/trunk.stl" scale="1 1 1" />
      </geometry>
      <material name="trunk_material">
        <color rgba="0.35 0.35 0.38 1.0" />
      </material>
    </visual>
    <collision>
      <origin xyz="0 0 0" rpy="0 0 0" />
      <geometry>
        <mesh filename="meshes/trunk.stl" scale="1 1 1" />
      </geometry>
    </collision>
  </link>
  <link name="leg_0_hip">
    <inertial>
      <origin xyz="-0.000000000 0.000000000 0.000000000" rpy="0 0 0" />
      <mass value="0.135343292" />
      <inertia ixx="0.000064817" ixy="-0.000000000" ixz="0.000000000" iyy="0.000064817" iyz="0.000000000" izz="0.000064817" />
    </inertial>
    <visual>
      <origin xyz="0 0 0" rpy="0 0 0" />
      <geometry>
        <mesh filename="meshes/leg_0_hip.stl" scale="1 1 1" />
      </geometry>
      <material name="joint_material">
        <color rgba="0.72 0.72 0.72 1.0" />
      </material>
    </visual>
    <collision>
      <origin xyz="0 0 0" rpy="0 0 0" />
      <geometry>
        <mesh filename="meshes/leg_0_hip.stl" scale="1 1 1" />
      </geometry>
    </collision>
  </link>
  <link name="leg_0_swing_node">
    <inertial>
      <origin xyz="-0.000000000 0.000000000 -0.000000000" rpy="0 0 0" />
      <mass value="0.037168651" />
      <inertia ixx="0.000007521" ixy="0.000000000" ixz="-0.000000000" iyy="0.000007521" iyz="0.000000000" izz="0.000007521" />
    </inertial>
    <visual>
      <origin xyz="0 0 0" rpy="0 0 0" />
      <geometry>
        <mesh filename="meshes/leg_0_swing_node.stl" scale="1 1 1" />
      </geometry>
      <material name="joint_material">
        <color rgba="0.72 0.72 0.72 1.0" />
      </material>
    </visual>
    <collision>
      <origin xyz="0 0 0" rpy="0 0 0" />
      <geometry>
        <mesh filename="meshes/leg_0_swing_node.stl" scale="1 1 1" />
      </geometry>
    </collision>
  </link>
  <link name="leg_0_upper">
    <inertial>
      <origin xyz="0.032626647 0.027354024 -0.133368884" rpy="0 0 0" />
      <mass value="0.220878453" />
      <inertia ixx="0.001383440" ixy="-0.000064900" ixz="0.000316429" iyy="0.001406438" iyz="0.000265292" izz="0.000167374" />
    </inertial>
    <visual>
      <origin xyz="0 0 0" rpy="0 0 0" />
      <geometry>
        <mesh filename="meshes/leg_0_upper.stl" scale="1 1 1" />
      </geometry>
      <material name="upper_link_material">
        <color rgba="0.15 0.46 0.65 1.0" />
      </material>
    </visual>
    <collision>
      <origin xyz="0 0 0" rpy="0 0 0" />
      <geometry>
        <mesh filename="meshes/leg_0_upper.stl" scale="1 1 1" />
      </geometry>
    </collision>
  </link>
  <link name="leg_0_knee">
    <inertial>
      <origin xyz="0.000000000 0.000000000 0.000000000" rpy="0 0 0" />
      <mass value="0.098665260" />
      <inertia ixx="0.000038274" ixy="-0.000000000" ixz="0.000000000" iyy="0.000038274" iyz="-0.000000000" izz="0.000038274" />
    </inertial>
    <visual>
      <origin xyz="0 0 0" rpy="0 0 0" />
      <geometry>
        <mesh filename="meshes/leg_0_knee.stl" scale="1 1 1" />
      </geometry>
      <material name="joint_material">
        <color rgba="0.72 0.72 0.72 1.0" />
      </material>
    </visual>
    <collision>
      <origin xyz="0 0 0" rpy="0 0 0" />
      <geometry>
        <mesh filename="meshes/leg_0_knee.stl" scale="1 1 1" />
      </geometry>
    </collision>
  </link>
  <link name="leg_0_lower">
    <inertial>
      <origin xyz="0.000288611 0.012772203 -0.149454968" rpy="0 0 0" />
      <mass value="0.200305203" />
      <inertia ixx="0.001515928" ixy="-0.000000244" ixz="0.000002854" iyy="0.001505141" iyz="0.000126295" izz="0.000038088" />
    </inertial>
    <visual>
      <origin xyz="0 0 0" rpy="0 0 0" />
      <geometry>
        <mesh filename="meshes/leg_0_lower.stl" scale="1 1 1" />
      </geometry>
      <material name="lower_link_material">
        <color rgba="0.11 0.60 0.44 1.0" />
      </material>
    </visual>
    <collision>
      <origin xyz="0 0 0" rpy="0 0 0" />
      <geometry>
        <mesh filename="meshes/leg_0_lower.stl" scale="1 1 1" />
      </geometry>
    </collision>
  </link>
  <link name="leg_0_foot">
    <inertial>
      <origin xyz="0.000000000 0.000000000 -0.000000000" rpy="0 0 0" />
      <mass value="0.057097951" />
      <inertia ixx="0.000015381" ixy="-0.000000000" ixz="-0.000000000" iyy="0.000015381" iyz="-0.000000000" izz="0.000015381" />
    </inertial>
    <visual>
      <origin xyz="0 0 0" rpy="0 0 0" />
      <geometry>
        <mesh filename="meshes/leg_0_foot.stl" scale="1 1 1" />
      </geometry>
      <material name="foot_material">
        <color rgba="0.90 0.52 0.14 1.0" />
      </material>
    </visual>
    <collision>
      <origin xyz="0 0 0" rpy="0 0 0" />
      <geometry>
        <mesh filename="meshes/leg_0_foot.stl" scale="1 1 1" />
      </geometry>
    </collision>
  </link>
  <link name="leg_1_hip">
    <inertial>
      <origin xyz="-0.000000000 0.000000000 0.000000000" rpy="0 0 0" />
      <mass value="0.135343292" />
      <inertia ixx="0.000064817" ixy="-0.000000000" ixz="0.000000000" iyy="0.000064817" iyz="0.000000000" izz="0.000064817" />
    </inertial>
    <visual>
      <origin xyz="0 0 0" rpy="0 0 0" />
      <geometry>
        <mesh filename="meshes/leg_1_hip.stl" scale="1 1 1" />
      </geometry>
      <material name="joint_material">
        <color rgba="0.72 0.72 0.72 1.0" />
      </material>
    </visual>
    <collision>
      <origin xyz="0 0 0" rpy="0 0 0" />
      <geometry>
        <mesh filename="meshes/leg_1_hip.stl" scale="1 1 1" />
      </geometry>
    </collision>
  </link>
  <link name="leg_1_swing_node">
    <inertial>
      <origin xyz="-0.000000000 0.000000000 -0.000000000" rpy="0 0 0" />
      <mass value="0.037168651" />
      <inertia ixx="0.000007521" ixy="0.000000000" ixz="-0.000000000" iyy="0.000007521" iyz="0.000000000" izz="0.000007521" />
    </inertial>
    <visual>
      <origin xyz="0 0 0" rpy="0 0 0" />
      <geometry>
        <mesh filename="meshes/leg_1_swing_node.stl" scale="1 1 1" />
      </geometry>
      <material name="joint_material">
        <color rgba="0.72 0.72 0.72 1.0" />
      </material>
    </visual>
    <collision>
      <origin xyz="0 0 0" rpy="0 0 0" />
      <geometry>
        <mesh filename="meshes/leg_1_swing_node.stl" scale="1 1 1" />
      </geometry>
    </collision>
  </link>
  <link name="leg_1_upper">
    <inertial>
      <origin xyz="-0.010501146 0.028188143 -0.136730225" rpy="0 0 0" />
      <mass value="0.220878453" />
      <inertia ixx="0.001452830" ixy="0.000021525" ixz="-0.000104412" iyy="0.001403069" iyz="0.000280272" izz="0.000101353" />
    </inertial>
    <visual>
      <origin xyz="0 0 0" rpy="0 0 0" />
      <geometry>
        <mesh filename="meshes/leg_1_upper.stl" scale="1 1 1" />
      </geometry>
      <material name="upper_link_material">
        <color rgba="0.15 0.46 0.65 1.0" />
      </material>
    </visual>
    <collision>
      <origin xyz="0 0 0" rpy="0 0 0" />
      <geometry>
        <mesh filename="meshes/leg_1_upper.stl" scale="1 1 1" />
      </geometry>
    </collision>
  </link>
  <link name="leg_1_knee">
    <inertial>
      <origin xyz="0.000000000 0.000000000 0.000000000" rpy="0 0 0" />
      <mass value="0.098665260" />
      <inertia ixx="0.000038274" ixy="-0.000000000" ixz="0.000000000" iyy="0.000038274" iyz="-0.000000000" izz="0.000038274" />
    </inertial>
    <visual>
      <origin xyz="0 0 0" rpy="0 0 0" />
      <geometry>
        <mesh filename="meshes/leg_1_knee.stl" scale="1 1 1" />
      </geometry>
      <material name="joint_material">
        <color rgba="0.72 0.72 0.72 1.0" />
      </material>
    </visual>
    <collision>
      <origin xyz="0 0 0" rpy="0 0 0" />
      <geometry>
        <mesh filename="meshes/leg_1_knee.stl" scale="1 1 1" />
      </geometry>
    </collision>
  </link>
  <link name="leg_1_lower">
    <inertial>
      <origin xyz="-0.004175855 0.011209215 -0.149522292" rpy="0 0 0" />
      <mass value="0.200305203" />
      <inertia ixx="0.001514780" ixy="0.000003097" ixz="-0.000041310" iyy="0.001507621" iyz="0.000110889" izz="0.000036756" />
    </inertial>
    <visual>
      <origin xyz="0 0 0" rpy="0 0 0" />
      <geometry>
        <mesh filename="meshes/leg_1_lower.stl" scale="1 1 1" />
      </geometry>
      <material name="lower_link_material">
        <color rgba="0.11 0.60 0.44 1.0" />
      </material>
    </visual>
    <collision>
      <origin xyz="0 0 0" rpy="0 0 0" />
      <geometry>
        <mesh filename="meshes/leg_1_lower.stl" scale="1 1 1" />
      </geometry>
    </collision>
  </link>
  <link name="leg_1_foot">
    <inertial>
      <origin xyz="0.000000000 0.000000000 -0.000000000" rpy="0 0 0" />
      <mass value="0.057097951" />
      <inertia ixx="0.000015381" ixy="-0.000000000" ixz="-0.000000000" iyy="0.000015381" iyz="-0.000000000" izz="0.000015381" />
    </inertial>
    <visual>
      <origin xyz="0 0 0" rpy="0 0 0" />
      <geometry>
        <mesh filename="meshes/leg_1_foot.stl" scale="1 1 1" />
      </geometry>
      <material name="foot_material">
        <color rgba="0.90 0.52 0.14 1.0" />
      </material>
    </visual>
    <collision>
      <origin xyz="0 0 0" rpy="0 0 0" />
      <geometry>
        <mesh filename="meshes/leg_1_foot.stl" scale="1 1 1" />
      </geometry>
    </collision>
  </link>
  <link name="leg_2_hip">
    <inertial>
      <origin xyz="-0.000000000 0.000000000 0.000000000" rpy="0 0 0" />
      <mass value="0.135343292" />
      <inertia ixx="0.000064817" ixy="-0.000000000" ixz="0.000000000" iyy="0.000064817" iyz="0.000000000" izz="0.000064817" />
    </inertial>
    <visual>
      <origin xyz="0 0 0" rpy="0 0 0" />
      <geometry>
        <mesh filename="meshes/leg_2_hip.stl" scale="1 1 1" />
      </geometry>
      <material name="joint_material">
        <color rgba="0.72 0.72 0.72 1.0" />
      </material>
    </visual>
    <collision>
      <origin xyz="0 0 0" rpy="0 0 0" />
      <geometry>
        <mesh filename="meshes/leg_2_hip.stl" scale="1 1 1" />
      </geometry>
    </collision>
  </link>
  <link name="leg_2_swing_node">
    <inertial>
      <origin xyz="-0.000000000 0.000000000 -0.000000000" rpy="0 0 0" />
      <mass value="0.037168651" />
      <inertia ixx="0.000007521" ixy="0.000000000" ixz="-0.000000000" iyy="0.000007521" iyz="0.000000000" izz="0.000007521" />
    </inertial>
    <visual>
      <origin xyz="0 0 0" rpy="0 0 0" />
      <geometry>
        <mesh filename="meshes/leg_2_swing_node.stl" scale="1 1 1" />
      </geometry>
      <material name="joint_material">
        <color rgba="0.72 0.72 0.72 1.0" />
      </material>
    </visual>
    <collision>
      <origin xyz="0 0 0" rpy="0 0 0" />
      <geometry>
        <mesh filename="meshes/leg_2_swing_node.stl" scale="1 1 1" />
      </geometry>
    </collision>
  </link>
  <link name="leg_2_upper">
    <inertial>
      <origin xyz="-0.041604993 0.014564415 -0.132879277" rpy="0 0 0" />
      <mass value="0.220878453" />
      <inertia ixx="0.001334974" ixy="0.000044064" ixz="-0.000402024" iyy="0.001445424" iyz="0.000140734" izz="0.000176854" />
    </inertial>
    <visual>
      <origin xyz="0 0 0" rpy="0 0 0" />
      <geometry>
        <mesh filename="meshes/leg_2_upper.stl" scale="1 1 1" />
      </geometry>
      <material name="upper_link_material">
        <color rgba="0.15 0.46 0.65 1.0" />
      </material>
    </visual>
    <collision>
      <origin xyz="0 0 0" rpy="0 0 0" />
      <geometry>
        <mesh filename="meshes/leg_2_upper.stl" scale="1 1 1" />
      </geometry>
    </collision>
  </link>
  <link name="leg_2_knee">
    <inertial>
      <origin xyz="0.000000000 0.000000000 0.000000000" rpy="0 0 0" />
      <mass value="0.098665260" />
      <inertia ixx="0.000038274" ixy="-0.000000000" ixz="0.000000000" iyy="0.000038274" iyz="-0.000000000" izz="0.000038274" />
    </inertial>
    <visual>
      <origin xyz="0 0 0" rpy="0 0 0" />
      <geometry>
        <mesh filename="meshes/leg_2_knee.stl" scale="1 1 1" />
      </geometry>
      <material name="joint_material">
        <color rgba="0.72 0.72 0.72 1.0" />
      </material>
    </visual>
    <collision>
      <origin xyz="0 0 0" rpy="0 0 0" />
      <geometry>
        <mesh filename="meshes/leg_2_knee.stl" scale="1 1 1" />
      </geometry>
    </collision>
  </link>
  <link name="leg_2_lower">
    <inertial>
      <origin xyz="-0.004975322 0.010348720 -0.149559855" rpy="0 0 0" />
      <mass value="0.200305203" />
      <inertia ixx="0.001514296" ixy="0.000003407" ixz="-0.000049232" iyy="0.001508848" iyz="0.000102402" izz="0.000036013" />
    </inertial>
    <visual>
      <origin xyz="0 0 0" rpy="0 0 0" />
      <geometry>
        <mesh filename="meshes/leg_2_lower.stl" scale="1 1 1" />
      </geometry>
      <material name="lower_link_material">
        <color rgba="0.11 0.60 0.44 1.0" />
      </material>
    </visual>
    <collision>
      <origin xyz="0 0 0" rpy="0 0 0" />
      <geometry>
        <mesh filename="meshes/leg_2_lower.stl" scale="1 1 1" />
      </geometry>
    </collision>
  </link>
  <link name="leg_2_foot">
    <inertial>
      <origin xyz="0.000000000 0.000000000 -0.000000000" rpy="0 0 0" />
      <mass value="0.057097951" />
      <inertia ixx="0.000015381" ixy="-0.000000000" ixz="-0.000000000" iyy="0.000015381" iyz="-0.000000000" izz="0.000015381" />
    </inertial>
    <visual>
      <origin xyz="0 0 0" rpy="0 0 0" />
      <geometry>
        <mesh filename="meshes/leg_2_foot.stl" scale="1 1 1" />
      </geometry>
      <material name="foot_material">
        <color rgba="0.90 0.52 0.14 1.0" />
      </material>
    </visual>
    <collision>
      <origin xyz="0 0 0" rpy="0 0 0" />
      <geometry>
        <mesh filename="meshes/leg_2_foot.stl" scale="1 1 1" />
      </geometry>
    </collision>
  </link>
  <link name="leg_3_hip">
    <inertial>
      <origin xyz="-0.000000000 0.000000000 0.000000000" rpy="0 0 0" />
      <mass value="0.135343292" />
      <inertia ixx="0.000064817" ixy="-0.000000000" ixz="0.000000000" iyy="0.000064817" iyz="0.000000000" izz="0.000064817" />
    </inertial>
    <visual>
      <origin xyz="0 0 0" rpy="0 0 0" />
      <geometry>
        <mesh filename="meshes/leg_3_hip.stl" scale="1 1 1" />
      </geometry>
      <material name="joint_material">
        <color rgba="0.72 0.72 0.72 1.0" />
      </material>
    </visual>
    <collision>
      <origin xyz="0 0 0" rpy="0 0 0" />
      <geometry>
        <mesh filename="meshes/leg_3_hip.stl" scale="1 1 1" />
      </geometry>
    </collision>
  </link>
  <link name="leg_3_swing_node">
    <inertial>
      <origin xyz="-0.000000000 0.000000000 -0.000000000" rpy="0 0 0" />
      <mass value="0.037168651" />
      <inertia ixx="0.000007521" ixy="0.000000000" ixz="-0.000000000" iyy="0.000007521" iyz="0.000000000" izz="0.000007521" />
    </inertial>
    <visual>
      <origin xyz="0 0 0" rpy="0 0 0" />
      <geometry>
        <mesh filename="meshes/leg_3_swing_node.stl" scale="1 1 1" />
      </geometry>
      <material name="joint_material">
        <color rgba="0.72 0.72 0.72 1.0" />
      </material>
    </visual>
    <collision>
      <origin xyz="0 0 0" rpy="0 0 0" />
      <geometry>
        <mesh filename="meshes/leg_3_swing_node.stl" scale="1 1 1" />
      </geometry>
    </collision>
  </link>
  <link name="leg_3_upper">
    <inertial>
      <origin xyz="-0.029903700 0.003257943 -0.136730225" rpy="0 0 0" />
      <mass value="0.220878453" />
      <inertia ixx="0.001395821" ixy="0.000007085" ixz="-0.000297330" iyy="0.001460077" iyz="0.000032393" izz="0.000101353" />
    </inertial>
    <visual>
      <origin xyz="0 0 0" rpy="0 0 0" />
      <geometry>
        <mesh filename="meshes/leg_3_upper.stl" scale="1 1 1" />
      </geometry>
      <material name="upper_link_material">
        <color rgba="0.15 0.46 0.65 1.0" />
      </material>
    </visual>
    <collision>
      <origin xyz="0 0 0" rpy="0 0 0" />
      <geometry>
        <mesh filename="meshes/leg_3_upper.stl" scale="1 1 1" />
      </geometry>
    </collision>
  </link>
  <link name="leg_3_knee">
    <inertial>
      <origin xyz="0.000000000 0.000000000 0.000000000" rpy="0 0 0" />
      <mass value="0.098665260" />
      <inertia ixx="0.000038274" ixy="-0.000000000" ixz="0.000000000" iyy="0.000038274" iyz="-0.000000000" izz="0.000038274" />
    </inertial>
    <visual>
      <origin xyz="0 0 0" rpy="0 0 0" />
      <geometry>
        <mesh filename="meshes/leg_3_knee.stl" scale="1 1 1" />
      </geometry>
      <material name="joint_material">
        <color rgba="0.72 0.72 0.72 1.0" />
      </material>
    </visual>
    <collision>
      <origin xyz="0 0 0" rpy="0 0 0" />
      <geometry>
        <mesh filename="meshes/leg_3_knee.stl" scale="1 1 1" />
      </geometry>
    </collision>
  </link>
  <link name="leg_3_lower">
    <inertial>
      <origin xyz="-0.011891418 0.001295544 -0.149522292" rpy="0 0 0" />
      <mass value="0.200305203" />
      <inertia ixx="0.001506578" ixy="0.000001019" ixz="-0.000117638" iyy="0.001515823" iyz="0.000012816" izz="0.000036756" />
    </inertial>
    <visual>
      <origin xyz="0 0 0" rpy="0 0 0" />
      <geometry>
        <mesh filename="meshes/leg_3_lower.stl" scale="1 1 1" />
      </geometry>
      <material name="lower_link_material">
        <color rgba="0.11 0.60 0.44 1.0" />
      </material>
    </visual>
    <collision>
      <origin xyz="0 0 0" rpy="0 0 0" />
      <geometry>
        <mesh filename="meshes/leg_3_lower.stl" scale="1 1 1" />
      </geometry>
    </collision>
  </link>
  <link name="leg_3_foot">
    <inertial>
      <origin xyz="0.000000000 0.000000000 -0.000000000" rpy="0 0 0" />
      <mass value="0.057097951" />
      <inertia ixx="0.000015381" ixy="-0.000000000" ixz="-0.000000000" iyy="0.000015381" iyz="-0.000000000" izz="0.000015381" />
    </inertial>
    <visual>
      <origin xyz="0 0 0" rpy="0 0 0" />
      <geometry>
        <mesh filename="meshes/leg_3_foot.stl" scale="1 1 1" />
      </geometry>
      <material name="foot_material">
        <color rgba="0.90 0.52 0.14 1.0" />
      </material>
    </visual>
    <collision>
      <origin xyz="0 0 0" rpy="0 0 0" />
      <geometry>
        <mesh filename="meshes/leg_3_foot.stl" scale="1 1 1" />
      </geometry>
    </collision>
  </link>
  <link name="leg_4_hip">
    <inertial>
      <origin xyz="-0.000000000 0.000000000 0.000000000" rpy="0 0 0" />
      <mass value="0.135343292" />
      <inertia ixx="0.000064817" ixy="-0.000000000" ixz="0.000000000" iyy="0.000064817" iyz="0.000000000" izz="0.000064817" />
    </inertial>
    <visual>
      <origin xyz="0 0 0" rpy="0 0 0" />
      <geometry>
        <mesh filename="meshes/leg_4_hip.stl" scale="1 1 1" />
      </geometry>
      <material name="joint_material">
        <color rgba="0.72 0.72 0.72 1.0" />
      </material>
    </visual>
    <collision>
      <origin xyz="0 0 0" rpy="0 0 0" />
      <geometry>
        <mesh filename="meshes/leg_4_hip.stl" scale="1 1 1" />
      </geometry>
    </collision>
  </link>
  <link name="leg_4_swing_node">
    <inertial>
      <origin xyz="-0.000000000 0.000000000 -0.000000000" rpy="0 0 0" />
      <mass value="0.037168651" />
      <inertia ixx="0.000007521" ixy="0.000000000" ixz="-0.000000000" iyy="0.000007521" iyz="0.000000000" izz="0.000007521" />
    </inertial>
    <visual>
      <origin xyz="0 0 0" rpy="0 0 0" />
      <geometry>
        <mesh filename="meshes/leg_4_swing_node.stl" scale="1 1 1" />
      </geometry>
      <material name="joint_material">
        <color rgba="0.72 0.72 0.72 1.0" />
      </material>
    </visual>
    <collision>
      <origin xyz="0 0 0" rpy="0 0 0" />
      <geometry>
        <mesh filename="meshes/leg_4_swing_node.stl" scale="1 1 1" />
      </geometry>
    </collision>
  </link>
  <link name="leg_4_upper">
    <inertial>
      <origin xyz="-0.018262392 -0.026873591 -0.136177440" rpy="0 0 0" />
      <mass value="0.220878453" />
      <inertia ixx="0.001436596" ixy="-0.000035689" ixz="-0.000180847" iyy="0.001408332" iyz="-0.000266121" izz="0.000112323" />
    </inertial>
    <visual>
      <origin xyz="0 0 0" rpy="0 0 0" />
      <geometry>
        <mesh filename="meshes/leg_4_upper.stl" scale="1 1 1" />
      </geometry>
      <material name="upper_link_material">
        <color rgba="0.15 0.46 0.65 1.0" />
      </material>
    </visual>
    <collision>
      <origin xyz="0 0 0" rpy="0 0 0" />
      <geometry>
        <mesh filename="meshes/leg_4_upper.stl" scale="1 1 1" />
      </geometry>
    </collision>
  </link>
  <link name="leg_4_knee">
    <inertial>
      <origin xyz="0.000000000 0.000000000 0.000000000" rpy="0 0 0" />
      <mass value="0.098665260" />
      <inertia ixx="0.000038274" ixy="-0.000000000" ixz="0.000000000" iyy="0.000038274" iyz="-0.000000000" izz="0.000038274" />
    </inertial>
    <visual>
      <origin xyz="0 0 0" rpy="0 0 0" />
      <geometry>
        <mesh filename="meshes/leg_4_knee.stl" scale="1 1 1" />
      </geometry>
      <material name="joint_material">
        <color rgba="0.72 0.72 0.72 1.0" />
      </material>
    </visual>
    <collision>
      <origin xyz="0 0 0" rpy="0 0 0" />
      <geometry>
        <mesh filename="meshes/leg_4_knee.stl" scale="1 1 1" />
      </geometry>
    </collision>
  </link>
  <link name="leg_4_lower">
    <inertial>
      <origin xyz="-0.018267408 -0.001165628 -0.148878955" rpy="0 0 0" />
      <mass value="0.200305203" />
      <inertia ixx="0.001493856" ixy="-0.000001409" ixz="-0.000179936" iyy="0.001515844" iyz="-0.000011482" izz="0.000049457" />
    </inertial>
    <visual>
      <origin xyz="0 0 0" rpy="0 0 0" />
      <geometry>
        <mesh filename="meshes/leg_4_lower.stl" scale="1 1 1" />
      </geometry>
      <material name="lower_link_material">
        <color rgba="0.11 0.60 0.44 1.0" />
      </material>
    </visual>
    <collision>
      <origin xyz="0 0 0" rpy="0 0 0" />
      <geometry>
        <mesh filename="meshes/leg_4_lower.stl" scale="1 1 1" />
      </geometry>
    </collision>
  </link>
  <link name="leg_4_foot">
    <inertial>
      <origin xyz="0.000000000 0.000000000 -0.000000000" rpy="0 0 0" />
      <mass value="0.057097951" />
      <inertia ixx="0.000015381" ixy="-0.000000000" ixz="-0.000000000" iyy="0.000015381" iyz="-0.000000000" izz="0.000015381" />
    </inertial>
    <visual>
      <origin xyz="0 0 0" rpy="0 0 0" />
      <geometry>
        <mesh filename="meshes/leg_4_foot.stl" scale="1 1 1" />
      </geometry>
      <material name="foot_material">
        <color rgba="0.90 0.52 0.14 1.0" />
      </material>
    </visual>
    <collision>
      <origin xyz="0 0 0" rpy="0 0 0" />
      <geometry>
        <mesh filename="meshes/leg_4_foot.stl" scale="1 1 1" />
      </geometry>
    </collision>
  </link>
  <link name="leg_5_hip">
    <inertial>
      <origin xyz="-0.000000000 0.000000000 0.000000000" rpy="0 0 0" />
      <mass value="0.135343292" />
      <inertia ixx="0.000064817" ixy="-0.000000000" ixz="0.000000000" iyy="0.000064817" iyz="0.000000000" izz="0.000064817" />
    </inertial>
    <visual>
      <origin xyz="0 0 0" rpy="0 0 0" />
      <geometry>
        <mesh filename="meshes/leg_5_hip.stl" scale="1 1 1" />
      </geometry>
      <material name="joint_material">
        <color rgba="0.72 0.72 0.72 1.0" />
      </material>
    </visual>
    <collision>
      <origin xyz="0 0 0" rpy="0 0 0" />
      <geometry>
        <mesh filename="meshes/leg_5_hip.stl" scale="1 1 1" />
      </geometry>
    </collision>
  </link>
  <link name="leg_5_swing_node">
    <inertial>
      <origin xyz="-0.000000000 0.000000000 -0.000000000" rpy="0 0 0" />
      <mass value="0.037168651" />
      <inertia ixx="0.000007521" ixy="0.000000000" ixz="-0.000000000" iyy="0.000007521" iyz="0.000000000" izz="0.000007521" />
    </inertial>
    <visual>
      <origin xyz="0 0 0" rpy="0 0 0" />
      <geometry>
        <mesh filename="meshes/leg_5_swing_node.stl" scale="1 1 1" />
      </geometry>
      <material name="joint_material">
        <color rgba="0.72 0.72 0.72 1.0" />
      </material>
    </visual>
    <collision>
      <origin xyz="0 0 0" rpy="0 0 0" />
      <geometry>
        <mesh filename="meshes/leg_5_swing_node.stl" scale="1 1 1" />
      </geometry>
    </collision>
  </link>
  <link name="leg_5_upper">
    <inertial>
      <origin xyz="-0.016448867 -0.025184921 -0.136730225" rpy="0 0 0" />
      <mass value="0.220878453" />
      <inertia ixx="0.001441174" ixy="-0.000030125" ixz="-0.000163550" iyy="0.001414725" iyz="-0.000250411" izz="0.000101353" />
    </inertial>
    <visual>
      <origin xyz="0 0 0" rpy="0 0 0" />
      <geometry>
        <mesh filename="meshes/leg_5_upper.stl" scale="1 1 1" />
      </geometry>
      <material name="upper_link_material">
        <color rgba="0.15 0.46 0.65 1.0" />
      </material>
    </visual>
    <collision>
      <origin xyz="0 0 0" rpy="0 0 0" />
      <geometry>
        <mesh filename="meshes/leg_5_upper.stl" scale="1 1 1" />
      </geometry>
    </collision>
  </link>
  <link name="leg_5_knee">
    <inertial>
      <origin xyz="0.000000000 0.000000000 0.000000000" rpy="0 0 0" />
      <mass value="0.098665260" />
      <inertia ixx="0.000038274" ixy="-0.000000000" ixz="0.000000000" iyy="0.000038274" iyz="-0.000000000" izz="0.000038274" />
    </inertial>
    <visual>
      <origin xyz="0 0 0" rpy="0 0 0" />
      <geometry>
        <mesh filename="meshes/leg_5_knee.stl" scale="1 1 1" />
      </geometry>
      <material name="joint_material">
        <color rgba="0.72 0.72 0.72 1.0" />
      </material>
    </visual>
    <collision>
      <origin xyz="0 0 0" rpy="0 0 0" />
      <geometry>
        <mesh filename="meshes/leg_5_knee.stl" scale="1 1 1" />
      </geometry>
    </collision>
  </link>
  <link name="leg_5_lower">
    <inertial>
      <origin xyz="-0.006541009 -0.010014962 -0.149522292" rpy="0 0 0" />
      <mass value="0.200305203" />
      <inertia ixx="0.001513103" ixy="-0.000004334" ixz="-0.000064708" iyy="0.001509298" iyz="-0.000099075" izz="0.000036756" />
    </inertial>
    <visual>
      <origin xyz="0 0 0" rpy="0 0 0" />
      <geometry>
        <mesh filename="meshes/leg_5_lower.stl" scale="1 1 1" />
      </geometry>
      <material name="lower_link_material">
        <color rgba="0.11 0.60 0.44 1.0" />
      </material>
    </visual>
    <collision>
      <origin xyz="0 0 0" rpy="0 0 0" />
      <geometry>
        <mesh filename="meshes/leg_5_lower.stl" scale="1 1 1" />
      </geometry>
    </collision>
  </link>
  <link name="leg_5_foot">
    <inertial>
      <origin xyz="0.000000000 0.000000000 -0.000000000" rpy="0 0 0" />
      <mass value="0.057097951" />
      <inertia ixx="0.000015381" ixy="-0.000000000" ixz="-0.000000000" iyy="0.000015381" iyz="-0.000000000" izz="0.000015381" />
    </inertial>
    <visual>
      <origin xyz="0 0 0" rpy="0 0 0" />
      <geometry>
        <mesh filename="meshes/leg_5_foot.stl" scale="1 1 1" />
      </geometry>
      <material name="foot_material">
        <color rgba="0.90 0.52 0.14 1.0" />
      </material>
    </visual>
    <collision>
      <origin xyz="0 0 0" rpy="0 0 0" />
      <geometry>
        <mesh filename="meshes/leg_5_foot.stl" scale="1 1 1" />
      </geometry>
    </collision>
  </link>
  <link name="leg_6_hip">
    <inertial>
      <origin xyz="-0.000000000 0.000000000 0.000000000" rpy="0 0 0" />
      <mass value="0.135343292" />
      <inertia ixx="0.000064817" ixy="-0.000000000" ixz="0.000000000" iyy="0.000064817" iyz="0.000000000" izz="0.000064817" />
    </inertial>
    <visual>
      <origin xyz="0 0 0" rpy="0 0 0" />
      <geometry>
        <mesh filename="meshes/leg_6_hip.stl" scale="1 1 1" />
      </geometry>
      <material name="joint_material">
        <color rgba="0.72 0.72 0.72 1.0" />
      </material>
    </visual>
    <collision>
      <origin xyz="0 0 0" rpy="0 0 0" />
      <geometry>
        <mesh filename="meshes/leg_6_hip.stl" scale="1 1 1" />
      </geometry>
    </collision>
  </link>
  <link name="leg_6_swing_node">
    <inertial>
      <origin xyz="-0.000000000 0.000000000 -0.000000000" rpy="0 0 0" />
      <mass value="0.037168651" />
      <inertia ixx="0.000007521" ixy="0.000000000" ixz="-0.000000000" iyy="0.000007521" iyz="0.000000000" izz="0.000007521" />
    </inertial>
    <visual>
      <origin xyz="0 0 0" rpy="0 0 0" />
      <geometry>
        <mesh filename="meshes/leg_6_swing_node.stl" scale="1 1 1" />
      </geometry>
      <material name="joint_material">
        <color rgba="0.72 0.72 0.72 1.0" />
      </material>
    </visual>
    <collision>
      <origin xyz="0 0 0" rpy="0 0 0" />
      <geometry>
        <mesh filename="meshes/leg_6_swing_node.stl" scale="1 1 1" />
      </geometry>
    </collision>
  </link>
  <link name="leg_6_upper">
    <inertial>
      <origin xyz="-0.005968841 -0.031037303 -0.136385699" rpy="0 0 0" />
      <mass value="0.220878453" />
      <inertia ixx="0.001458258" ixy="-0.000013472" ixz="-0.000059198" iyy="0.001390798" iyz="-0.000307824" izz="0.000108195" />
    </inertial>
    <visual>
      <origin xyz="0 0 0" rpy="0 0 0" />
      <geometry>
        <mesh filename="meshes/leg_6_upper.stl" scale="1 1 1" />
      </geometry>
      <material name="upper_link_material">
        <color rgba="0.15 0.46 0.65 1.0" />
      </material>
    </visual>
    <collision>
      <origin xyz="0 0 0" rpy="0 0 0" />
      <geometry>
        <mesh filename="meshes/leg_6_upper.stl" scale="1 1 1" />
      </geometry>
    </collision>
  </link>
  <link name="leg_6_knee">
    <inertial>
      <origin xyz="0.000000000 0.000000000 0.000000000" rpy="0 0 0" />
      <mass value="0.098665260" />
      <inertia ixx="0.000038274" ixy="-0.000000000" ixz="0.000000000" iyy="0.000038274" iyz="-0.000000000" izz="0.000038274" />
    </inertial>
    <visual>
      <origin xyz="0 0 0" rpy="0 0 0" />
      <geometry>
        <mesh filename="meshes/leg_6_knee.stl" scale="1 1 1" />
      </geometry>
      <material name="joint_material">
        <color rgba="0.72 0.72 0.72 1.0" />
      </material>
    </visual>
    <collision>
      <origin xyz="0 0 0" rpy="0 0 0" />
      <geometry>
        <mesh filename="meshes/leg_6_knee.stl" scale="1 1 1" />
      </geometry>
    </collision>
  </link>
  <link name="leg_6_lower">
    <inertial>
      <origin xyz="0.012169706 -0.014112939 -0.148837909" rpy="0 0 0" />
      <mass value="0.200305203" />
      <inertia ixx="0.001506135" ixy="0.000011363" ixz="0.000119840" iyy="0.001502756" iyz="-0.000138976" izz="0.000050266" />
    </inertial>
    <visual>
      <origin xyz="0 0 0" rpy="0 0 0" />
      <geometry>
        <mesh filename="meshes/leg_6_lower.stl" scale="1 1 1" />
      </geometry>
      <material name="lower_link_material">
        <color rgba="0.11 0.60 0.44 1.0" />
      </material>
    </visual>
    <collision>
      <origin xyz="0 0 0" rpy="0 0 0" />
      <geometry>
        <mesh filename="meshes/leg_6_lower.stl" scale="1 1 1" />
      </geometry>
    </collision>
  </link>
  <link name="leg_6_foot">
    <inertial>
      <origin xyz="0.000000000 0.000000000 -0.000000000" rpy="0 0 0" />
      <mass value="0.057097951" />
      <inertia ixx="0.000015381" ixy="-0.000000000" ixz="-0.000000000" iyy="0.000015381" iyz="-0.000000000" izz="0.000015381" />
    </inertial>
    <visual>
      <origin xyz="0 0 0" rpy="0 0 0" />
      <geometry>
        <mesh filename="meshes/leg_6_foot.stl" scale="1 1 1" />
      </geometry>
      <material name="foot_material">
        <color rgba="0.90 0.52 0.14 1.0" />
      </material>
    </visual>
    <collision>
      <origin xyz="0 0 0" rpy="0 0 0" />
      <geometry>
        <mesh filename="meshes/leg_6_foot.stl" scale="1 1 1" />
      </geometry>
    </collision>
  </link>
  <link name="leg_7_hip">
    <inertial>
      <origin xyz="-0.000000000 0.000000000 0.000000000" rpy="0 0 0" />
      <mass value="0.135343292" />
      <inertia ixx="0.000064817" ixy="-0.000000000" ixz="0.000000000" iyy="0.000064817" iyz="0.000000000" izz="0.000064817" />
    </inertial>
    <visual>
      <origin xyz="0 0 0" rpy="0 0 0" />
      <geometry>
        <mesh filename="meshes/leg_7_hip.stl" scale="1 1 1" />
      </geometry>
      <material name="joint_material">
        <color rgba="0.72 0.72 0.72 1.0" />
      </material>
    </visual>
    <collision>
      <origin xyz="0 0 0" rpy="0 0 0" />
      <geometry>
        <mesh filename="meshes/leg_7_hip.stl" scale="1 1 1" />
      </geometry>
    </collision>
  </link>
  <link name="leg_7_swing_node">
    <inertial>
      <origin xyz="-0.000000000 0.000000000 -0.000000000" rpy="0 0 0" />
      <mass value="0.037168651" />
      <inertia ixx="0.000007521" ixy="0.000000000" ixz="-0.000000000" iyy="0.000007521" iyz="0.000000000" izz="0.000007521" />
    </inertial>
    <visual>
      <origin xyz="0 0 0" rpy="0 0 0" />
      <geometry>
        <mesh filename="meshes/leg_7_swing_node.stl" scale="1 1 1" />
      </geometry>
      <material name="joint_material">
        <color rgba="0.72 0.72 0.72 1.0" />
      </material>
    </visual>
    <collision>
      <origin xyz="0 0 0" rpy="0 0 0" />
      <geometry>
        <mesh filename="meshes/leg_7_swing_node.stl" scale="1 1 1" />
      </geometry>
    </collision>
  </link>
  <link name="leg_7_upper">
    <inertial>
      <origin xyz="0.009877511 -0.020000369 -0.138211505" rpy="0 0 0" />
      <mass value="0.220878453" />
      <inertia ixx="0.001453754" ixy="0.000014366" ixz="0.000099275" iyy="0.001431760" iyz="-0.000201016" izz="0.000071737" />
    </inertial>
    <visual>
      <origin xyz="0 0 0" rpy="0 0 0" />
      <geometry>
        <mesh filename="meshes/leg_7_upper.stl" scale="1 1 1" />
      </geometry>
      <material name="upper_link_material">
        <color rgba="0.15 0.46 0.65 1.0" />
      </material>
    </visual>
    <collision>
      <origin xyz="0 0 0" rpy="0 0 0" />
      <geometry>
        <mesh filename="meshes/leg_7_upper.stl" scale="1 1 1" />
      </geometry>
    </collision>
  </link>
  <link name="leg_7_knee">
    <inertial>
      <origin xyz="0.000000000 0.000000000 0.000000000" rpy="0 0 0" />
      <mass value="0.098665260" />
      <inertia ixx="0.000038274" ixy="-0.000000000" ixz="0.000000000" iyy="0.000038274" iyz="-0.000000000" izz="0.000038274" />
    </inertial>
    <visual>
      <origin xyz="0 0 0" rpy="0 0 0" />
      <geometry>
        <mesh filename="meshes/leg_7_knee.stl" scale="1 1 1" />
      </geometry>
      <material name="joint_material">
        <color rgba="0.72 0.72 0.72 1.0" />
      </material>
    </visual>
    <collision>
      <origin xyz="0 0 0" rpy="0 0 0" />
      <geometry>
        <mesh filename="meshes/leg_7_knee.stl" scale="1 1 1" />
      </geometry>
    </collision>
  </link>
  <link name="leg_7_lower">
    <inertial>
      <origin xyz="0.019270358 -0.008953071 -0.148487359" rpy="0 0 0" />
      <mass value="0.200305203" />
      <inertia ixx="0.001491365" ixy="0.000011415" ixz="0.000189316" iyy="0.001510630" iyz="-0.000087957" izz="0.000057162" />
    </inertial>
    <visual>
      <origin xyz="0 0 0" rpy="0 0 0" />
      <geometry>
        <mesh filename="meshes/leg_7_lower.stl" scale="1 1 1" />
      </geometry>
      <material name="lower_link_material">
        <color rgba="0.11 0.60 0.44 1.0" />
      </material>
    </visual>
    <collision>
      <origin xyz="0 0 0" rpy="0 0 0" />
      <geometry>
        <mesh filename="meshes/leg_7_lower.stl" scale="1 1 1" />
      </geometry>
    </collision>
  </link>
  <link name="leg_7_foot">
    <inertial>
      <origin xyz="0.000000000 0.000000000 -0.000000000" rpy="0 0 0" />
      <mass value="0.057097951" />
      <inertia ixx="0.000015381" ixy="-0.000000000" ixz="-0.000000000" iyy="0.000015381" iyz="-0.000000000" izz="0.000015381" />
    </inertial>
    <visual>
      <origin xyz="0 0 0" rpy="0 0 0" />
      <geometry>
        <mesh filename="meshes/leg_7_foot.stl" scale="1 1 1" />
      </geometry>
      <material name="foot_material">
        <color rgba="0.90 0.52 0.14 1.0" />
      </material>
    </visual>
    <collision>
      <origin xyz="0 0 0" rpy="0 0 0" />
      <geometry>
        <mesh filename="meshes/leg_7_foot.stl" scale="1 1 1" />
      </geometry>
    </collision>
  </link>
  <link name="leg_8_hip">
    <inertial>
      <origin xyz="-0.000000000 0.000000000 0.000000000" rpy="0 0 0" />
      <mass value="0.135343292" />
      <inertia ixx="0.000064817" ixy="-0.000000000" ixz="0.000000000" iyy="0.000064817" iyz="0.000000000" izz="0.000064817" />
    </inertial>
    <visual>
      <origin xyz="0 0 0" rpy="0 0 0" />
      <geometry>
        <mesh filename="meshes/leg_8_hip.stl" scale="1 1 1" />
      </geometry>
      <material name="joint_material">
        <color rgba="0.72 0.72 0.72 1.0" />
      </material>
    </visual>
    <collision>
      <origin xyz="0 0 0" rpy="0 0 0" />
      <geometry>
        <mesh filename="meshes/leg_8_hip.stl" scale="1 1 1" />
      </geometry>
    </collision>
  </link>
  <link name="leg_8_swing_node">
    <inertial>
      <origin xyz="-0.000000000 0.000000000 -0.000000000" rpy="0 0 0" />
      <mass value="0.037168651" />
      <inertia ixx="0.000007521" ixy="0.000000000" ixz="-0.000000000" iyy="0.000007521" iyz="0.000000000" izz="0.000007521" />
    </inertial>
    <visual>
      <origin xyz="0 0 0" rpy="0 0 0" />
      <geometry>
        <mesh filename="meshes/leg_8_swing_node.stl" scale="1 1 1" />
      </geometry>
      <material name="joint_material">
        <color rgba="0.72 0.72 0.72 1.0" />
      </material>
    </visual>
    <collision>
      <origin xyz="0 0 0" rpy="0 0 0" />
      <geometry>
        <mesh filename="meshes/leg_8_swing_node.stl" scale="1 1 1" />
      </geometry>
    </collision>
  </link>
  <link name="leg_8_upper">
    <inertial>
      <origin xyz="0.032213155 -0.019339417 -0.134864004" rpy="0 0 0" />
      <mass value="0.220878453" />
      <inertia ixx="0.001385389" ixy="0.000045303" ixz="0.000315921" iyy="0.001433651" iyz="-0.000189666" izz="0.000138211" />
    </inertial>
    <visual>
      <origin xyz="0 0 0" rpy="0 0 0" />
      <geometry>
        <mesh filename="meshes/leg_8_upper.stl" scale="1 1 1" />
      </geometry>
      <material name="upper_link_material">
        <color rgba="0.15 0.46 0.65 1.0" />
      </material>
    </visual>
    <collision>
      <origin xyz="0 0 0" rpy="0 0 0" />
      <geometry>
        <mesh filename="meshes/leg_8_upper.stl" scale="1 1 1" />
      </geometry>
    </collision>
  </link>
  <link name="leg_8_knee">
    <inertial>
      <origin xyz="0.000000000 0.000000000 0.000000000" rpy="0 0 0" />
      <mass value="0.098665260" />
      <inertia ixx="0.000038274" ixy="-0.000000000" ixz="0.000000000" iyy="0.000038274" iyz="-0.000000000" izz="0.000038274" />
    </inertial>
    <visual>
      <origin xyz="0 0 0" rpy="0 0 0" />
      <geometry>
        <mesh filename="meshes/leg_8_knee.stl" scale="1 1 1" />
      </geometry>
      <material name="joint_material">
        <color rgba="0.72 0.72 0.72 1.0" />
      </material>
    </visual>
    <collision>
      <origin xyz="0 0 0" rpy="0 0 0" />
      <geometry>
        <mesh filename="meshes/leg_8_knee.stl" scale="1 1 1" />
      </geometry>
    </collision>
  </link>
  <link name="leg_8_lower">
    <inertial>
      <origin xyz="0.014843247 0.006003044 -0.149143024" rpy="0 0 0" />
      <mass value="0.200305203" />
      <inertia ixx="0.001501357" ixy="-0.000005895" ixz="0.000146467" iyy="0.001513549" iyz="0.000059236" izz="0.000044250" />
    </inertial>
    <visual>
      <origin xyz="0 0 0" rpy="0 0 0" />
      <geometry>
        <mesh filename="meshes/leg_8_lower.stl" scale="1 1 1" />
      </geometry>
      <material name="lower_link_material">
        <color rgba="0.11 0.60 0.44 1.0" />
      </material>
    </visual>
    <collision>
      <origin xyz="0 0 0" rpy="0 0 0" />
      <geometry>
        <mesh filename="meshes/leg_8_lower.stl" scale="1 1 1" />
      </geometry>
    </collision>
  </link>
  <link name="leg_8_foot">
    <inertial>
      <origin xyz="0.000000000 0.000000000 -0.000000000" rpy="0 0 0" />
      <mass value="0.057097951" />
      <inertia ixx="0.000015381" ixy="-0.000000000" ixz="-0.000000000" iyy="0.000015381" iyz="-0.000000000" izz="0.000015381" />
    </inertial>
    <visual>
      <origin xyz="0 0 0" rpy="0 0 0" />
      <geometry>
        <mesh filename="meshes/leg_8_foot.stl" scale="1 1 1" />
      </geometry>
      <material name="foot_material">
        <color rgba="0.90 0.52 0.14 1.0" />
      </material>
    </visual>
    <collision>
      <origin xyz="0 0 0" rpy="0 0 0" />
      <geometry>
        <mesh filename="meshes/leg_8_foot.stl" scale="1 1 1" />
      </geometry>
    </collision>
  </link>
  <link name="leg_9_hip">
    <inertial>
      <origin xyz="-0.000000000 0.000000000 0.000000000" rpy="0 0 0" />
      <mass value="0.135343292" />
      <inertia ixx="0.000064817" ixy="-0.000000000" ixz="0.000000000" iyy="0.000064817" iyz="0.000000000" izz="0.000064817" />
    </inertial>
    <visual>
      <origin xyz="0 0 0" rpy="0 0 0" />
      <geometry>
        <mesh filename="meshes/leg_9_hip.stl" scale="1 1 1" />
      </geometry>
      <material name="joint_material">
        <color rgba="0.72 0.72 0.72 1.0" />
      </material>
    </visual>
    <collision>
      <origin xyz="0 0 0" rpy="0 0 0" />
      <geometry>
        <mesh filename="meshes/leg_9_hip.stl" scale="1 1 1" />
      </geometry>
    </collision>
  </link>
  <link name="leg_9_swing_node">
    <inertial>
      <origin xyz="-0.000000000 0.000000000 -0.000000000" rpy="0 0 0" />
      <mass value="0.037168651" />
      <inertia ixx="0.000007521" ixy="0.000000000" ixz="-0.000000000" iyy="0.000007521" iyz="0.000000000" izz="0.000007521" />
    </inertial>
    <visual>
      <origin xyz="0 0 0" rpy="0 0 0" />
      <geometry>
        <mesh filename="meshes/leg_9_swing_node.stl" scale="1 1 1" />
      </geometry>
      <material name="joint_material">
        <color rgba="0.72 0.72 0.72 1.0" />
      </material>
    </visual>
    <collision>
      <origin xyz="0 0 0" rpy="0 0 0" />
      <geometry>
        <mesh filename="meshes/leg_9_swing_node.stl" scale="1 1 1" />
      </geometry>
    </collision>
  </link>
  <link name="leg_9_upper">
    <inertial>
      <origin xyz="0.042409028 0.005897461 -0.133291764" rpy="0 0 0" />
      <mass value="0.220878453" />
      <inertia ixx="0.001330062" ixy="-0.000018187" ixz="0.000411065" iyy="0.001458320" iyz="0.000057163" izz="0.000168870" />
    </inertial>
    <visual>
      <origin xyz="0 0 0" rpy="0 0 0" />
      <geometry>
        <mesh filename="meshes/leg_9_upper.stl" scale="1 1 1" />
      </geometry>
      <material name="upper_link_material">
        <color rgba="0.15 0.46 0.65 1.0" />
      </material>
    </visual>
    <collision>
      <origin xyz="0 0 0" rpy="0 0 0" />
      <geometry>
        <mesh filename="meshes/leg_9_upper.stl" scale="1 1 1" />
      </geometry>
    </collision>
  </link>
  <link name="leg_9_knee">
    <inertial>
      <origin xyz="0.000000000 0.000000000 0.000000000" rpy="0 0 0" />
      <mass value="0.098665260" />
      <inertia ixx="0.000038274" ixy="-0.000000000" ixz="0.000000000" iyy="0.000038274" iyz="-0.000000000" izz="0.000038274" />
    </inertial>
    <visual>
      <origin xyz="0 0 0" rpy="0 0 0" />
      <geometry>
        <mesh filename="meshes/leg_9_knee.stl" scale="1 1 1" />
      </geometry>
      <material name="joint_material">
        <color rgba="0.72 0.72 0.72 1.0" />
      </material>
    </visual>
    <collision>
      <origin xyz="0 0 0" rpy="0 0 0" />
      <geometry>
        <mesh filename="meshes/leg_9_knee.stl" scale="1 1 1" />
      </geometry>
    </collision>
  </link>
  <link name="leg_9_lower">
    <inertial>
      <origin xyz="0.007002601 0.010452975 -0.149471398" rpy="0 0 0" />
      <mass value="0.200305203" />
      <inertia ixx="0.001512689" ixy="-0.000004843" ixz="0.000069251" iyy="0.001508705" iyz="0.000103373" izz="0.000037763" />
    </inertial>
    <visual>
      <origin xyz="0 0 0" rpy="0 0 0" />
      <geometry>
        <mesh filename="meshes/leg_9_lower.stl" scale="1 1 1" />
      </geometry>
      <material name="lower_link_material">
        <color rgba="0.11 0.60 0.44 1.0" />
      </material>
    </visual>
    <collision>
      <origin xyz="0 0 0" rpy="0 0 0" />
      <geometry>
        <mesh filename="meshes/leg_9_lower.stl" scale="1 1 1" />
      </geometry>
    </collision>
  </link>
  <link name="leg_9_foot">
    <inertial>
      <origin xyz="0.000000000 0.000000000 -0.000000000" rpy="0 0 0" />
      <mass value="0.057097951" />
      <inertia ixx="0.000015381" ixy="-0.000000000" ixz="-0.000000000" iyy="0.000015381" iyz="-0.000000000" izz="0.000015381" />
    </inertial>
    <visual>
      <origin xyz="0 0 0" rpy="0 0 0" />
      <geometry>
        <mesh filename="meshes/leg_9_foot.stl" scale="1 1 1" />
      </geometry>
      <material name="foot_material">
        <color rgba="0.90 0.52 0.14 1.0" />
      </material>
    </visual>
    <collision>
      <origin xyz="0 0 0" rpy="0 0 0" />
      <geometry>
        <mesh filename="meshes/leg_9_foot.stl" scale="1 1 1" />
      </geometry>
    </collision>
  </link>
  <joint name="leg_0_mount" type="fixed">
    <parent link="base_link" />
    <child link="leg_0_hip" />
    <origin xyz="-0.131024023 -0.220000000 -0.090000000" rpy="0.000000000 0.000000000 0.000000000" />
  </joint>
  <joint name="leg_0_lift" type="revolute">
    <parent link="leg_0_hip" />
    <child link="leg_0_swing_node" />
    <origin xyz="0.000000000 0.000000000 0.000000000" rpy="0.000000000 0.000000000 0.000000000" />
    <axis xyz="1.000000000 0.000000000 0.000000000" />
    <limit lower="-0.800000000" upper="0.950000000" effort="25.000000000" velocity="2.500000000" />
    <dynamics damping="0.200000000" friction="0.050000000" />
  </joint>
  <joint name="leg_0_swing" type="revolute">
    <parent link="leg_0_swing_node" />
    <child link="leg_0_upper" />
    <origin xyz="0.000000000 0.000000000 0.000000000" rpy="0.000000000 0.000000000 0.000000000" />
    <axis xyz="0.000000000 0.000000000 1.000000000" />
    <limit lower="-0.550000000" upper="0.550000000" effort="20.000000000" velocity="2.000000000" />
    <dynamics damping="0.150000000" friction="0.040000000" />
  </joint>
  <joint name="leg_0_knee_mount" type="fixed">
    <parent link="leg_0_upper" />
    <child link="leg_0_knee" />
    <origin xyz="0.065253293 0.054708047 -0.266737769" rpy="0.000000000 0.000000000 0.000000000" />
  </joint>
  <joint name="leg_0_drop" type="revolute">
    <parent link="leg_0_knee" />
    <child link="leg_0_lower" />
    <origin xyz="0.000000000 0.000000000 0.000000000" rpy="0.000000000 0.000000000 0.000000000" />
    <axis xyz="1.000000000 0.000000000 0.000000000" />
    <limit lower="-0.100000000" upper="1.100000000" effort="18.000000000" velocity="2.300000000" />
    <dynamics damping="0.120000000" friction="0.030000000" />
  </joint>
  <joint name="leg_0_foot_mount" type="fixed">
    <parent link="leg_0_lower" />
    <child link="leg_0_foot" />
    <origin xyz="0.000577223 0.025544406 -0.298909936" rpy="0.000000000 0.000000000 0.000000000" />
  </joint>
  <joint name="leg_1_mount" type="fixed">
    <parent link="base_link" />
    <child link="leg_1_hip" />
    <origin xyz="0.085489387 -0.220000000 -0.090000000" rpy="0.000000000 0.000000000 0.000000000" />
  </joint>
  <joint name="leg_1_lift" type="revolute">
    <parent link="leg_1_hip" />
    <child link="leg_1_swing_node" />
    <origin xyz="0.000000000 0.000000000 0.000000000" rpy="0.000000000 0.000000000 0.000000000" />
    <axis xyz="1.000000000 0.000000000 0.000000000" />
    <limit lower="-0.800000000" upper="0.950000000" effort="25.000000000" velocity="2.500000000" />
    <dynamics damping="0.200000000" friction="0.050000000" />
  </joint>
  <joint name="leg_1_swing" type="revolute">
    <parent link="leg_1_swing_node" />
    <child link="leg_1_upper" />
    <origin xyz="0.000000000 0.000000000 0.000000000" rpy="0.000000000 0.000000000 0.000000000" />
    <axis xyz="0.000000000 0.000000000 1.000000000" />
    <limit lower="-0.120000000" upper="0.120000000" effort="20.000000000" velocity="2.000000000" />
    <dynamics damping="0.150000000" friction="0.040000000" />
  </joint>
  <joint name="leg_1_knee_mount" type="fixed">
    <parent link="leg_1_upper" />
    <child link="leg_1_knee" />
    <origin xyz="-0.021002291 0.056376286 -0.273460451" rpy="0.000000000 0.000000000 0.000000000" />
  </joint>
  <joint name="leg_1_drop" type="revolute">
    <parent link="leg_1_knee" />
    <child link="leg_1_lower" />
    <origin xyz="0.000000000 0.000000000 0.000000000" rpy="0.000000000 0.000000000 0.000000000" />
    <axis xyz="1.000000000 0.000000000 0.000000000" />
    <limit lower="-0.100000000" upper="1.100000000" effort="18.000000000" velocity="2.300000000" />
    <dynamics damping="0.120000000" friction="0.030000000" />
  </joint>
  <joint name="leg_1_foot_mount" type="fixed">
    <parent link="leg_1_lower" />
    <child link="leg_1_foot" />
    <origin xyz="-0.008351710 0.022418430 -0.299044584" rpy="0.000000000 0.000000000 0.000000000" />
  </joint>
  <joint name="leg_2_mount" type="fixed">
    <parent link="base_link" />
    <child link="leg_2_hip" />
    <origin xyz="0.300537158 -0.207714671 -0.090000000" rpy="0.000000000 0.000000000 0.000000000" />
  </joint>
  <joint name="leg_2_lift" type="revolute">
    <parent link="leg_2_hip" />
    <child link="leg_2_swing_node" />
    <origin xyz="0.000000000 0.000000000 0.000000000" rpy="0.000000000 0.000000000 0.000000000" />
    <axis xyz="0.971934458 0.235251799 0.000000000" />
    <limit lower="-0.800000000" upper="0.950000000" effort="25.000000000" velocity="2.500000000" />
    <dynamics damping="0.200000000" friction="0.050000000" />
  </joint>
  <joint name="leg_2_swing" type="revolute">
    <parent link="leg_2_swing_node" />
    <child link="leg_2_upper" />
    <origin xyz="0.000000000 0.000000000 0.000000000" rpy="0.000000000 0.000000000 0.000000000" />
    <axis xyz="0.000000000 0.000000000 1.000000000" />
    <limit lower="-0.550000000" upper="0.550000000" effort="20.000000000" velocity="2.000000000" />
    <dynamics damping="0.150000000" friction="0.040000000" />
  </joint>
  <joint name="leg_2_knee_mount" type="fixed">
    <parent link="leg_2_upper" />
    <child link="leg_2_knee" />
    <origin xyz="-0.083209987 0.029128831 -0.265758555" rpy="0.000000000 0.000000000 0.000000000" />
  </joint>
  <joint name="leg_2_drop" type="revolute">
    <parent link="leg_2_knee" />
    <child link="leg_2_lower" />
    <origin xyz="0.000000000 0.000000000 0.000000000" rpy="0.000000000 0.000000000 0.000000000" />
    <axis xyz="0.971934458 0.235251799 0.000000000" />
    <limit lower="-0.100000000" upper="1.100000000" effort="18.000000000" velocity="2.300000000" />
    <dynamics damping="0.120000000" friction="0.030000000" />
  </joint>
  <joint name="leg_2_foot_mount" type="fixed">
    <parent link="leg_2_lower" />
    <child link="leg_2_foot" />
    <origin xyz="-0.009950645 0.020697439 -0.299119710" rpy="0.000000000 0.000000000 0.000000000" />
  </joint>
  <joint name="leg_3_mount" type="fixed">
    <parent link="base_link" />
    <child link="leg_3_hip" />
    <origin xyz="0.360000000 -0.037988471 -0.090000000" rpy="0.000000000 0.000000000 0.000000000" />
  </joint>
  <joint name="leg_3_lift" type="revolute">
    <parent link="leg_3_hip" />
    <child link="leg_3_swing_node" />
    <origin xyz="0.000000000 0.000000000 0.000000000" rpy="0.000000000 0.000000000 0.000000000" />
    <axis xyz="0.000000000 1.000000000 0.000000000" />
    <limit lower="-0.800000000" upper="0.950000000" effort="25.000000000" velocity="2.500000000" />
    <dynamics damping="0.200000000" friction="0.050000000" />
  </joint>
  <joint name="leg_3_swing" type="revolute">
    <parent link="leg_3_swing_node" />
    <child link="leg_3_upper" />
    <origin xyz="0.000000000 0.000000000 0.000000000" rpy="0.000000000 0.000000000 0.000000000" />
    <axis xyz="0.000000000 0.000000000 1.000000000" />
    <limit lower="-0.120000000" upper="0.120000000" effort="20.000000000" velocity="2.000000000" />
    <dynamics damping="0.150000000" friction="0.040000000" />
  </joint>
  <joint name="leg_3_knee_mount" type="fixed">
    <parent link="leg_3_upper" />
    <child link="leg_3_knee" />
    <origin xyz="-0.059807400 0.006515886 -0.273460451" rpy="0.000000000 0.000000000 0.000000000" />
  </joint>
  <joint name="leg_3_drop" type="revolute">
    <parent link="leg_3_knee" />
    <child link="leg_3_lower" />
    <origin xyz="0.000000000 0.000000000 0.000000000" rpy="0.000000000 0.000000000 0.000000000" />
    <axis xyz="0.000000000 1.000000000 0.000000000" />
    <limit lower="-0.100000000" upper="1.100000000" effort="18.000000000" velocity="2.300000000" />
    <dynamics damping="0.120000000" friction="0.030000000" />
  </joint>
  <joint name="leg_3_foot_mount" type="fixed">
    <parent link="leg_3_lower" />
    <child link="leg_3_foot" />
    <origin xyz="-0.023782836 0.002591088 -0.299044584" rpy="0.000000000 0.000000000 0.000000000" />
  </joint>
  <joint name="leg_4_mount" type="fixed">
    <parent link="base_link" />
    <child link="leg_4_hip" />
    <origin xyz="0.341098952 0.171282828 -0.090000000" rpy="0.000000000 0.000000000 0.000000000" />
  </joint>
  <joint name="leg_4_lift" type="revolute">
    <parent link="leg_4_hip" />
    <child link="leg_4_swing_node" />
    <origin xyz="0.000000000 0.000000000 0.000000000" rpy="0.000000000 0.000000000 0.000000000" />
    <axis xyz="-0.668216856 0.743966554 0.000000000" />
    <limit lower="-0.800000000" upper="0.950000000" effort="25.000000000" velocity="2.500000000" />
    <dynamics damping="0.200000000" friction="0.050000000" />
  </joint>
  <joint name="leg_4_swing" type="revolute">
    <parent link="leg_4_swing_node" />
    <child link="leg_4_upper" />
    <origin xyz="0.000000000 0.000000000 0.000000000" rpy="0.000000000 0.000000000 0.000000000" />
    <axis xyz="0.000000000 0.000000000 1.000000000" />
    <limit lower="-0.550000000" upper="0.550000000" effort="20.000000000" velocity="2.000000000" />
    <dynamics damping="0.150000000" friction="0.040000000" />
  </joint>
  <joint name="leg_4_knee_mount" type="fixed">
    <parent link="leg_4_upper" />
    <child link="leg_4_knee" />
    <origin xyz="-0.036524783 -0.053747182 -0.272354880" rpy="0.000000000 0.000000000 0.000000000" />
  </joint>
  <joint name="leg_4_drop" type="revolute">
    <parent link="leg_4_knee" />
    <child link="leg_4_lower" />
    <origin xyz="0.000000000 0.000000000 0.000000000" rpy="0.000000000 0.000000000 0.000000000" />
    <axis xyz="-0.668216856 0.743966554 0.000000000" />
    <limit lower="-0.100000000" upper="1.100000000" effort="18.000000000" velocity="2.300000000" />
    <dynamics damping="0.120000000" friction="0.030000000" />
  </joint>
  <joint name="leg_4_foot_mount" type="fixed">
    <parent link="leg_4_lower" />
    <child link="leg_4_foot" />
    <origin xyz="-0.036534817 -0.002331257 -0.297757909" rpy="0.000000000 0.000000000 0.000000000" />
  </joint>
  <joint name="leg_5_mount" type="fixed">
    <parent link="base_link" />
    <child link="leg_5_hip" />
    <origin xyz="0.146311702 0.220000000 -0.090000000" rpy="0.000000000 0.000000000 0.000000000" />
  </joint>
  <joint name="leg_5_lift" type="revolute">
    <parent link="leg_5_hip" />
    <child link="leg_5_swing_node" />
    <origin xyz="0.000000000 0.000000000 0.000000000" rpy="0.000000000 0.000000000 0.000000000" />
    <axis xyz="-1.000000000 0.000000000 0.000000000" />
    <limit lower="-0.800000000" upper="0.950000000" effort="25.000000000" velocity="2.500000000" />
    <dynamics damping="0.200000000" friction="0.050000000" />
  </joint>
  <joint name="leg_5_swing" type="revolute">
    <parent link="leg_5_swing_node" />
    <child link="leg_5_upper" />
    <origin xyz="0.000000000 0.000000000 0.000000000" rpy="0.000000000 0.000000000 0.000000000" />
    <axis xyz="0.000000000 0.000000000 1.000000000" />
    <limit lower="-0.120000000" upper="0.120000000" effort="20.000000000" velocity="2.000000000" />
    <dynamics damping="0.150000000" friction="0.040000000" />
  </joint>
  <joint name="leg_5_knee_mount" type="fixed">
    <parent link="leg_5_upper" />
    <child link="leg_5_knee" />
    <origin xyz="-0.032897735 -0.050369842 -0.273460451" rpy="0.000000000 0.000000000 0.000000000" />
  </joint>
  <joint name="leg_5_drop" type="revolute">
    <parent link="leg_5_knee" />
    <child link="leg_5_lower" />
    <origin xyz="0.000000000 0.000000000 0.000000000" rpy="0.000000000 0.000000000 0.000000000" />
    <axis xyz="-1.000000000 0.000000000 0.000000000" />
    <limit lower="-0.100000000" upper="1.100000000" effort="18.000000000" velocity="2.300000000" />
    <dynamics damping="0.120000000" friction="0.030000000" />
  </joint>
  <joint name="leg_5_foot_mount" type="fixed">
    <parent link="leg_5_lower" />
    <child link="leg_5_foot" />
    <origin xyz="-0.013082017 -0.020029924 -0.299044584" rpy="0.000000000 0.000000000 0.000000000" />
  </joint>
  <joint name="leg_6_mount" type="fixed">
    <parent link="base_link" />
    <child link="leg_6_hip" />
    <origin xyz="-0.070201708 0.220000000 -0.090000000" rpy="0.000000000 0.000000000 0.000000000" />
  </joint>
  <joint name="leg_6_lift" type="revolute">
    <parent link="leg_6_hip" />
    <child link="leg_6_swing_node" />
    <origin xyz="0.000000000 0.000000000 0.000000000" rpy="0.000000000 0.000000000 0.000000000" />
    <axis xyz="-1.000000000 0.000000000 0.000000000" />
    <limit lower="-0.800000000" upper="0.950000000" effort="25.000000000" velocity="2.500000000" />
    <dynamics damping="0.200000000" friction="0.050000000" />
  </joint>
  <joint name="leg_6_swing" type="revolute">
    <parent link="leg_6_swing_node" />
    <child link="leg_6_upper" />
    <origin xyz="0.000000000 0.000000000 0.000000000" rpy="0.000000000 0.000000000 0.000000000" />
    <axis xyz="0.000000000 0.000000000 1.000000000" />
    <limit lower="-0.550000000" upper="0.550000000" effort="20.000000000" velocity="2.000000000" />
    <dynamics damping="0.150000000" friction="0.040000000" />
  </joint>
  <joint name="leg_6_knee_mount" type="fixed">
    <parent link="leg_6_upper" />
    <child link="leg_6_knee" />
    <origin xyz="-0.011937681 -0.062074605 -0.272771397" rpy="0.000000000 0.000000000 0.000000000" />
  </joint>
  <joint name="leg_6_drop" type="revolute">
    <parent link="leg_6_knee" />
    <child link="leg_6_lower" />
    <origin xyz="0.000000000 0.000000000 0.000000000" rpy="0.000000000 0.000000000 0.000000000" />
    <axis xyz="-1.000000000 0.000000000 0.000000000" />
    <limit lower="-0.100000000" upper="1.100000000" effort="18.000000000" velocity="2.300000000" />
    <dynamics damping="0.120000000" friction="0.030000000" />
  </joint>
  <joint name="leg_6_foot_mount" type="fixed">
    <parent link="leg_6_lower" />
    <child link="leg_6_foot" />
    <origin xyz="0.024339412 -0.028225878 -0.297675818" rpy="0.000000000 0.000000000 0.000000000" />
  </joint>
  <joint name="leg_7_mount" type="fixed">
    <parent link="base_link" />
    <child link="leg_7_hip" />
    <origin xyz="-0.286715118 0.220000000 -0.090000000" rpy="0.000000000 0.000000000 0.000000000" />
  </joint>
  <joint name="leg_7_lift" type="revolute">
    <parent link="leg_7_hip" />
    <child link="leg_7_swing_node" />
    <origin xyz="0.000000000 0.000000000 0.000000000" rpy="0.000000000 0.000000000 0.000000000" />
    <axis xyz="-1.000000000 0.000000000 0.000000000" />
    <limit lower="-0.800000000" upper="0.950000000" effort="25.000000000" velocity="2.500000000" />
    <dynamics damping="0.200000000" friction="0.050000000" />
  </joint>
  <joint name="leg_7_swing" type="revolute">
    <parent link="leg_7_swing_node" />
    <child link="leg_7_upper" />
    <origin xyz="0.000000000 0.000000000 0.000000000" rpy="0.000000000 0.000000000 0.000000000" />
    <axis xyz="0.000000000 0.000000000 1.000000000" />
    <limit lower="-0.550000000" upper="0.550000000" effort="20.000000000" velocity="2.000000000" />
    <dynamics damping="0.150000000" friction="0.040000000" />
  </joint>
  <joint name="leg_7_knee_mount" type="fixed">
    <parent link="leg_7_upper" />
    <child link="leg_7_knee" />
    <origin xyz="0.019755023 -0.040000737 -0.276423009" rpy="0.000000000 0.000000000 0.000000000" />
  </joint>
  <joint name="leg_7_drop" type="revolute">
    <parent link="leg_7_knee" />
    <child link="leg_7_lower" />
    <origin xyz="0.000000000 0.000000000 0.000000000" rpy="0.000000000 0.000000000 0.000000000" />
    <axis xyz="-1.000000000 0.000000000 0.000000000" />
    <limit lower="-0.100000000" upper="1.100000000" effort="18.000000000" velocity="2.300000000" />
    <dynamics damping="0.120000000" friction="0.030000000" />
  </joint>
  <joint name="leg_7_foot_mount" type="fixed">
    <parent link="leg_7_lower" />
    <child link="leg_7_foot" />
    <origin xyz="0.038540715 -0.017906143 -0.296974718" rpy="0.000000000 0.000000000 0.000000000" />
  </joint>
  <joint name="leg_8_mount" type="fixed">
    <parent link="base_link" />
    <child link="leg_8_hip" />
    <origin xyz="-0.360000000 0.036464697 -0.090000000" rpy="0.000000000 0.000000000 0.000000000" />
  </joint>
  <joint name="leg_8_lift" type="revolute">
    <parent link="leg_8_hip" />
    <child link="leg_8_swing_node" />
    <origin xyz="0.000000000 0.000000000 0.000000000" rpy="0.000000000 0.000000000 0.000000000" />
    <axis xyz="0.000000000 -1.000000000 0.000000000" />
    <limit lower="-0.800000000" upper="0.950000000" effort="25.000000000" velocity="2.500000000" />
    <dynamics damping="0.200000000" friction="0.050000000" />
  </joint>
  <joint name="leg_8_swing" type="revolute">
    <parent link="leg_8_swing_node" />
    <child link="leg_8_upper" />
    <origin xyz="0.000000000 0.000000000 0.000000000" rpy="0.000000000 0.000000000 0.000000000" />
    <axis xyz="0.000000000 0.000000000 1.000000000" />
    <limit lower="-0.550000000" upper="0.550000000" effort="20.000000000" velocity="2.000000000" />
    <dynamics damping="0.150000000" friction="0.040000000" />
  </joint>
  <joint name="leg_8_knee_mount" type="fixed">
    <parent link="leg_8_upper" />
    <child link="leg_8_knee" />
    <origin xyz="0.064426311 -0.038678835 -0.269728008" rpy="0.000000000 0.000000000 0.000000000" />
  </joint>
  <joint name="leg_8_drop" type="revolute">
    <parent link="leg_8_knee" />
    <child link="leg_8_lower" />
    <origin xyz="0.000000000 0.000000000 0.000000000" rpy="0.000000000 0.000000000 0.000000000" />
    <axis xyz="0.000000000 -1.000000000 0.000000000" />
    <limit lower="-0.100000000" upper="1.100000000" effort="18.000000000" velocity="2.300000000" />
    <dynamics damping="0.120000000" friction="0.030000000" />
  </joint>
  <joint name="leg_8_foot_mount" type="fixed">
    <parent link="leg_8_lower" />
    <child link="leg_8_foot" />
    <origin xyz="0.029686494 0.012006088 -0.298286047" rpy="0.000000000 0.000000000 0.000000000" />
  </joint>
  <joint name="leg_9_mount" type="fixed">
    <parent link="base_link" />
    <child link="leg_9_hip" />
    <origin xyz="-0.332078851 -0.164250359 -0.090000000" rpy="0.000000000 0.000000000 0.000000000" />
  </joint>
  <joint name="leg_9_lift" type="revolute">
    <parent link="leg_9_hip" />
    <child link="leg_9_swing_node" />
    <origin xyz="0.000000000 0.000000000 0.000000000" rpy="0.000000000 0.000000000 0.000000000" />
    <axis xyz="0.857204399 -0.514976329 0.000000000" />
    <limit lower="-0.800000000" upper="0.950000000" effort="25.000000000" velocity="2.500000000" />
    <dynamics damping="0.200000000" friction="0.050000000" />
  </joint>
  <joint name="leg_9_swing" type="revolute">
    <parent link="leg_9_swing_node" />
    <child link="leg_9_upper" />
    <origin xyz="0.000000000 0.000000000 0.000000000" rpy="0.000000000 0.000000000 0.000000000" />
    <axis xyz="0.000000000 0.000000000 1.000000000" />
    <limit lower="-0.550000000" upper="0.550000000" effort="20.000000000" velocity="2.000000000" />
    <dynamics damping="0.150000000" friction="0.040000000" />
  </joint>
  <joint name="leg_9_knee_mount" type="fixed">
    <parent link="leg_9_upper" />
    <child link="leg_9_knee" />
    <origin xyz="0.084818056 0.011794922 -0.266583528" rpy="0.000000000 0.000000000 0.000000000" />
  </joint>
  <joint name="leg_9_drop" type="revolute">
    <parent link="leg_9_knee" />
    <child link="leg_9_lower" />
    <origin xyz="0.000000000 0.000000000 0.000000000" rpy="0.000000000 0.000000000 0.000000000" />
    <axis xyz="0.857204399 -0.514976329 0.000000000" />
    <limit lower="-0.100000000" upper="1.100000000" effort="18.000000000" velocity="2.300000000" />
    <dynamics damping="0.120000000" friction="0.030000000" />
  </joint>
  <joint name="leg_9_foot_mount" type="fixed">
    <parent link="leg_9_lower" />
    <child link="leg_9_foot" />
    <origin xyz="0.014005202 0.020905950 -0.298942796" rpy="0.000000000 0.000000000 0.000000000" />
  </joint>
</robot>