<?xml version='1.0' encoding='utf-8'?>
<robot name="variant_04_seed75">
  <link name="base_link">
    <inertial>
      <origin xyz="0.043206546 -0.011896479 0.000000000" rpy="0 0 0" />
      <mass value="34.659569688" />
      <inertia ixx="0.773905060" ixy="-0.093059054" ixz="-0.000000000" iyy="0.845383531" iyz="0.000000000" izz="1.432126915" />
    </inertial>
    <visual>
      <origin xyz="0 0 0" rpy="0 0 0" />
      <geometry>
        <mesh filename="meshes/trunk.stl" scale="1 1 1" />
      </geometry>
      <material name="trunk_material">
        <color rgba="0.35 0.35 0.38 1.0" />
      </material>
    </visual>
    <collision>
      <origin xyz="0 0 0" rpy="0 0 0" />
      <geometry>
        <mesh filename="meshes/trunk.stl" scale="1 1 1" />
      </geometry>
    </collision>
  </link>
  <link name="leg_0_hip">
    <inertial>
      <origin xyz="-0.000000000 0.000000000 0.000000000" rpy="0 0 0" />
      <mass value="0.135343292" />
      <inertia ixx="0.000064817" ixy="-0.000000000" ixz="0.000000000" iyy="0.000064817" iyz="0.000000000" izz="0.000064817" />
    </inertial>
    <visual>
      <origin xyz="0 0 0" rpy="0 0 0" />
      <geometry>
        <mesh filename="meshes/leg_0_hip.stl" scale="1 1 1" />
      </geometry>
      <material name="joint_material">
        <color rgba="0.72 0.72 0.72 1.0" />
      </material>
    </visual>
    <collision>
      <origin xyz="0 0 0" rpy="0 0 0" />
      <geometry>
        <mesh filename="meshes/leg_0_hip.stl" scale="1 1 1" />
      </geometry>
    </collision>
  </link>
  <link name="leg_0_swing_node">
    <inertial>
      <origin xyz="-0.000000000 0.000000000 -0.000000000" rpy="0 0 0" />
      <mass value="0.037168651" />
      <inertia ixx="0.000007521" ixy="0.000000000" ixz="-0.000000000" iyy="0.000007521" iyz="0.000000000" izz="0.000007521" />
    </inertial>
    <visual>
      <origin xyz="0 0 0" rpy="0 0 0" />
      <geometry>
        <mesh filename="meshes/leg_0_swing_node.stl" scale="1 1 1" />
      </geometry>
      <material name="joint_material">
        <color rgba="0.72 0.72 0.72 1.0" />
      </material>
    </visual>
    <collision>
      <origin xyz="0 0 0" rpy="0 0 0" />
      <geometry>
        <mesh filename="meshes/leg_0_swing_node.stl" scale="1 1 1" />
      </geometry>
    </collision>
  </link>
  <link name="leg_0_upper">
    <inertial>
      <origin xyz="0.002843403 -0.139059190 -0.015951697" rpy="0 0 0" />
      <mass value="0.220878453" />
      <inertia ixx="0.001460261" ixy="0.000028753" ixz="0.000003298" iyy="0.000054645" iyz="-0.000161308" izz="0.001442345" />
    </inertial>
    <visual>
      <origin xyz="0 0 0" rpy="0 0 0" />
      <geometry>
        <mesh filename="meshes/leg_0_upper.stl" scale="1 1 1" />
      </geometry>
      <material name="upper_link_material">
        <color rgba="0.15 0.46 0.65 1.0" />
      </material>
    </visual>
    <collision>
      <origin xyz="0 0 0" rpy="0 0 0" />
      <geometry>
        <mesh filename="meshes/leg_0_upper.stl" scale="1 1 1" />
      </geometry>
    </collision>
  </link>
  <link name="leg_0_knee">
    <inertial>
      <origin xyz="0.000000000 0.000000000 0.000000000" rpy="0 0 0" />
      <mass value="0.098665260" />
      <inertia ixx="0.000038274" ixy="-0.000000000" ixz="0.000000000" iyy="0.000038274" iyz="-0.000000000" izz="0.000038274" />
    </inertial>
    <visual>
      <origin xyz="0 0 0" rpy="0 0 0" />
      <geometry>
        <mesh filename="meshes/leg_0_knee.stl" scale="1 1 1" />
      </geometry>
      <material name="joint_material">
        <color rgba="0.72 0.72 0.72 1.0" />
      </material>
    </visual>
    <collision>
      <origin xyz="0 0 0" rpy="0 0 0" />
      <geometry>
        <mesh filename="meshes/leg_0_knee.stl" scale="1 1 1" />
      </geometry>
    </collision>
  </link>
  <link name="leg_0_lower">
    <inertial>
      <origin xyz="0.020836493 -0.011797842 -0.148076506" rpy="0 0 0" />
      <mass value="0.200305203" />
      <inertia ixx="0.001487209" ixy="0.000016264" ixz="0.000204136" iyy="0.001506725" iyz="-0.000115584" izz="0.000065223" />
    </inertial>
    <visual>
      <origin xyz="0 0 0" rpy="0 0 0" />
      <geometry>
        <mesh filename="meshes/leg_0_lower.stl" scale="1 1 1" />
      </geometry>
      <material name="lower_link_material">
        <color rgba="0.11 0.60 0.44 1.0" />
      </material>
    </visual>
    <collision>
      <origin xyz="0 0 0" rpy="0 0 0" />
      <geometry>
        <mesh filename="meshes/leg_0_lower.stl" scale="1 1 1" />
      </geometry>
    </collision>
  </link>
  <link name="leg_0_foot">
    <inertial>
      <origin xyz="0.000000000 0.000000000 -0.000000000" rpy="0 0 0" />
      <mass value="0.057097951" />
      <inertia ixx="0.000015381" ixy="-0.000000000" ixz="-0.000000000" iyy="0.000015381" iyz="-0.000000000" izz="0.000015381" />
    </inertial>
    <visual>
      <origin xyz="0 0 0" rpy="0 0 0" />
      <geometry>
        <mesh filename="meshes/leg_0_foot.stl" scale="1 1 1" />
      </geometry>
      <material name="foot_material">
        <color rgba="0.90 0.52 0.14 1.0" />
      </material>
    </visual>
    <collision>
      <origin xyz="0 0 0" rpy="0 0 0" />
      <geometry>
        <mesh filename="meshes/leg_0_foot.stl" scale="1 1 1" />
      </geometry>
    </collision>
  </link>
  <link name="leg_1_hip">
    <inertial>
      <origin xyz="-0.000000000 0.000000000 0.000000000" rpy="0 0 0" />
      <mass value="0.135343292" />
      <inertia ixx="0.000064817" ixy="-0.000000000" ixz="0.000000000" iyy="0.000064817" iyz="0.000000000" izz="0.000064817" />
    </inertial>
    <visual>
      <origin xyz="0 0 0" rpy="0 0 0" />
      <geometry>
        <mesh filename="meshes/leg_1_hip.stl" scale="1 1 1" />
      </geometry>
      <material name="joint_material">
        <color rgba="0.72 0.72 0.72 1.0" />
      </material>
    </visual>
    <collision>
      <origin xyz="0 0 0" rpy="0 0 0" />
      <geometry>
        <mesh filename="meshes/leg_1_hip.stl" scale="1 1 1" />
      </geometry>
    </collision>
  </link>
  <link name="leg_1_swing_node">
    <inertial>
      <origin xyz="-0.000000000 0.000000000 -0.000000000" rpy="0 0 0" />
      <mass value="0.037168651" />
      <inertia ixx="0.000007521" ixy="0.000000000" ixz="-0.000000000" iyy="0.000007521" iyz="0.000000000" izz="0.000007521" />
    </inertial>
    <visual>
      <origin xyz="0 0 0" rpy="0 0 0" />
      <geometry>
        <mesh filename="meshes/leg_1_swing_node.stl" scale="1 1 1" />
      </geometry>
      <material name="joint_material">
        <color rgba="0.72 0.72 0.72 1.0" />
      </material>
    </visual>
    <collision>
      <origin xyz="0 0 0" rpy="0 0 0" />
      <geometry>
        <mesh filename="meshes/leg_1_swing_node.stl" scale="1 1 1" />
      </geometry>
    </collision>
  </link>
  <link name="leg_1_upper">
    <inertial>
      <origin xyz="0.065665758 0.122620251 -0.015883393" rpy="0 0 0" />
      <mass value="0.220878453" />
      <inertia ixx="0.001147285" ixy="-0.000585531" ixz="0.000075846" iyy="0.000367463" iyz="0.000141630" izz="0.001442503" />
    </inertial>
    <visual>
      <origin xyz="0 0 0" rpy="0 0 0" />
      <geometry>
        <mesh filename="meshes/leg_1_upper.stl" scale="1 1 1" />
      </geometry>
      <material name="upper_link_material">
        <color rgba="0.15 0.46 0.65 1.0" />
      </material>
    </visual>
    <collision>
      <origin xyz="0 0 0" rpy="0 0 0" />
      <geometry>
        <mesh filename="meshes/leg_1_upper.stl" scale="1 1 1" />
      </geometry>
    </collision>
  </link>
  <link name="leg_1_knee">
    <inertial>
      <origin xyz="0.000000000 0.000000000 0.000000000" rpy="0 0 0" />
      <mass value="0.098665260" />
      <inertia ixx="0.000038274" ixy="-0.000000000" ixz="0.000000000" iyy="0.000038274" iyz="-0.000000000" izz="0.000038274" />
    </inertial>
    <visual>
      <origin xyz="0 0 0" rpy="0 0 0" />
      <geometry>
        <mesh filename="meshes/leg_1_knee.stl" scale="1 1 1" />
      </geometry>
      <material name="joint_material">
        <color rgba="0.72 0.72 0.72 1.0" />
      </material>
    </visual>
    <collision>
      <origin xyz="0 0 0" rpy="0 0 0" />
      <geometry>
        <mesh filename="meshes/leg_1_knee.stl" scale="1 1 1" />
      </geometry>
    </collision>
  </link>
  <link name="leg_1_lower">
    <inertial>
      <origin xyz="0.023618475 0.000989850 -0.148125581" rpy="0 0 0" />
      <mass value="0.200305203" />
      <inertia ixx="0.001479026" ixy="-0.000001547" ixz="0.000231468" iyy="0.001515869" iyz="0.000009701" izz="0.000064261" />
    </inertial>
    <visual>
      <origin xyz="0 0 0" rpy="0 0 0" />
      <geometry>
        <mesh filename="meshes/leg_1_lower.stl" scale="1 1 1" />
      </geometry>
      <material name="lower_link_material">
        <color rgba="0.11 0.60 0.44 1.0" />
      </material>
    </visual>
    <collision>
      <origin xyz="0 0 0" rpy="0 0 0" />
      <geometry>
        <mesh filename="meshes/leg_1_lower.stl" scale="1 1 1" />
      </geometry>
    </collision>
  </link>
  <link name="leg_1_foot">
    <inertial>
      <origin xyz="0.000000000 0.000000000 -0.000000000" rpy="0 0 0" />
      <mass value="0.057097951" />
      <inertia ixx="0.000015381" ixy="-0.000000000" ixz="-0.000000000" iyy="0.000015381" iyz="-0.000000000" izz="0.000015381" />
    </inertial>
    <visual>
      <origin xyz="0 0 0" rpy="0 0 0" />
      <geometry>
        <mesh filename="meshes/leg_1_foot.stl" scale="1 1 1" />
      </geometry>
      <material name="foot_material">
        <color rgba="0.90 0.52 0.14 1.0" />
      </material>
    </visual>
    <collision>
      <origin xyz="0 0 0" rpy="0 0 0" />
      <geometry>
        <mesh filename="meshes/leg_1_foot.stl" scale="1 1 1" />
      </geometry>
    </collision>
  </link>
  <link name="leg_2_hip">
    <inertial>
      <origin xyz="-0.000000000 0.000000000 0.000000000" rpy="0 0 0" />
      <mass value="0.135343292" />
      <inertia ixx="0.000064817" ixy="-0.000000000" ixz="0.000000000" iyy="0.000064817" iyz="0.000000000" izz="0.000064817" />
    </inertial>
    <visual>
      <origin xyz="0 0 0" rpy="0 0 0" />
      <geometry>
        <mesh filename="meshes/leg_2_hip.stl" scale="1 1 1" />
      </geometry>
      <material name="joint_material">
        <color rgba="0.72 0.72 0.72 1.0" />
      </material>
    </visual>
    <collision>
      <origin xyz="0 0 0" rpy="0 0 0" />
      <geometry>
        <mesh filename="meshes/leg_2_hip.stl" scale="1 1 1" />
      </geometry>
    </collision>
  </link>
  <link name="leg_2_swing_node">
    <inertial>
      <origin xyz="-0.000000000 0.000000000 -0.000000000" rpy="0 0 0" />
      <mass value="0.037168651" />
      <inertia ixx="0.000007521" ixy="0.000000000" ixz="-0.000000000" iyy="0.000007521" iyz="0.000000000" izz="0.000007521" />
    </inertial>
    <visual>
      <origin xyz="0 0 0" rpy="0 0 0" />
      <geometry>
        <mesh filename="meshes/leg_2_swing_node.stl" scale="1 1 1" />
      </geometry>
      <material name="joint_material">
        <color rgba="0.72 0.72 0.72 1.0" />
      </material>
    </visual>
    <collision>
      <origin xyz="0 0 0" rpy="0 0 0" />
      <geometry>
        <mesh filename="meshes/leg_2_swing_node.stl" scale="1 1 1" />
      </geometry>
    </collision>
  </link>
  <link name="leg_2_upper">
    <inertial>
      <origin xyz="0.112394253 0.080788155 -0.020995378" rpy="0 0 0" />
      <mass value="0.220878453" />
      <inertia ixx="0.000542226" ixy="-0.000660299" ixz="0.000171600" iyy="0.000986231" iyz="0.000123345" izz="0.001428794" />
    </inertial>
    <visual>
      <origin xyz="0 0 0" rpy="0 0 0" />
      <geometry>
        <mesh filename="meshes/leg_2_upper.stl" scale="1 1 1" />
      </geometry>
      <material name="upper_link_material">
        <color rgba="0.15 0.46 0.65 1.0" />
      </material>
    </visual>
    <collision>
      <origin xyz="0 0 0" rpy="0 0 0" />
      <geometry>
        <mesh filename="meshes/leg_2_upper.stl" scale="1 1 1" />
      </geometry>
    </collision>
  </link>
  <link name="leg_2_knee">
    <inertial>
      <origin xyz="0.000000000 0.000000000 0.000000000" rpy="0 0 0" />
      <mass value="0.098665260" />
      <inertia ixx="0.000038274" ixy="-0.000000000" ixz="0.000000000" iyy="0.000038274" iyz="-0.000000000" izz="0.000038274" />
    </inertial>
    <visual>
      <origin xyz="0 0 0" rpy="0 0 0" />
      <geometry>
        <mesh filename="meshes/leg_2_knee.stl" scale="1 1 1" />
      </geometry>
      <material name="joint_material">
        <color rgba="0.72 0.72 0.72 1.0" />
      </material>
    </visual>
    <collision>
      <origin xyz="0 0 0" rpy="0 0 0" />
      <geometry>
        <mesh filename="meshes/leg_2_knee.stl" scale="1 1 1" />
      </geometry>
    </collision>
  </link>
  <link name="leg_2_lower">
    <inertial>
      <origin xyz="0.006259232 0.034989233 -0.145727745" rpy="0 0 0" />
      <mass value="0.200305203" />
      <inertia ixx="0.001513342" ixy="-0.000014490" ixz="0.000060349" iyy="0.001434935" iyz="0.000337353" izz="0.000110880" />
    </inertial>
    <visual>
      <origin xyz="0 0 0" rpy="0 0 0" />
      <geometry>
        <mesh filename="meshes/leg_2_lower.stl" scale="1 1 1" />
      </geometry>
      <material name="lower_link_material">
        <color rgba="0.11 0.60 0.44 1.0" />
      </material>
    </visual>
    <collision>
      <origin xyz="0 0 0" rpy="0 0 0" />
      <geometry>
        <mesh filename="meshes/leg_2_lower.stl" scale="1 1 1" />
      </geometry>
    </collision>
  </link>
  <link name="leg_2_foot">
    <inertial>
      <origin xyz="0.000000000 0.000000000 -0.000000000" rpy="0 0 0" />
      <mass value="0.057097951" />
      <inertia ixx="0.000015381" ixy="-0.000000000" ixz="-0.000000000" iyy="0.000015381" iyz="-0.000000000" izz="0.000015381" />
    </inertial>
    <visual>
      <origin xyz="0 0 0" rpy="0 0 0" />
      <geometry>
        <mesh filename="meshes/leg_2_foot.stl" scale="1 1 1" />
      </geometry>
      <material name="foot_material">
        <color rgba="0.90 0.52 0.14 1.0" />
      </material>
    </visual>
    <collision>
      <origin xyz="0 0 0" rpy="0 0 0" />
      <geometry>
        <mesh filename="meshes/leg_2_foot.stl" scale="1 1 1" />
      </geometry>
    </collision>
  </link>
  <link name="leg_3_hip">
    <inertial>
      <origin xyz="-0.000000000 0.000000000 0.000000000" rpy="0 0 0" />
      <mass value="0.135343292" />
      <inertia ixx="0.000064817" ixy="-0.000000000" ixz="0.000000000" iyy="0.000064817" iyz="0.000000000" izz="0.000064817" />
    </inertial>
    <visual>
      <origin xyz="0 0 0" rpy="0 0 0" />
      <geometry>
        <mesh filename="meshes/leg_3_hip.stl" scale="1 1 1" />
      </geometry>
      <material name="joint_material">
        <color rgba="0.72 0.72 0.72 1.0" />
      </material>
    </visual>
    <collision>
      <origin xyz="0 0 0" rpy="0 0 0" />
      <geometry>
        <mesh filename="meshes/leg_3_hip.stl" scale="1 1 1" />
      </geometry>
    </collision>
  </link>
  <link name="leg_3_swing_node">
    <inertial>
      <origin xyz="-0.000000000 0.000000000 -0.000000000" rpy="0 0 0" />
      <mass value="0.037168651" />
      <inertia ixx="0.000007521" ixy="0.000000000" ixz="-0.000000000" iyy="0.000007521" iyz="0.000000000" izz="0.000007521" />
    </inertial>
    <visual>
      <origin xyz="0 0 0" rpy="0 0 0" />
      <geometry>
        <mesh filename="meshes/leg_3_swing_node.stl" scale="1 1 1" />
      </geometry>
      <material name="joint_material">
        <color rgba="0.72 0.72 0.72 1.0" />
      </material>
    </visual>
    <collision>
      <origin xyz="0 0 0" rpy="0 0 0" />
      <geometry>
        <mesh filename="meshes/leg_3_swing_node.stl" scale="1 1 1" />
      </geometry>
    </collision>
  </link>
  <link name="leg_3_upper">
    <inertial>
      <origin xyz="0.085375147 0.109958437 -0.014840026" rpy="0 0 0" />
      <mass value="0.220878453" />
      <inertia ixx="0.000930805" ixy="-0.000682667" ixz="0.000092133" iyy="0.000581612" iyz="0.000118662" izz="0.001444834" />
    </inertial>
    <visual>
      <origin xyz="0 0 0" rpy="0 0 0" />
      <geometry>
        <mesh filename="meshes/leg_3_upper.stl" scale="1 1 1" />
      </geometry>
      <material name="upper_link_material">
        <color rgba="0.15 0.46 0.65 1.0" />
      </material>
    </visual>
    <collision>
      <origin xyz="0 0 0" rpy="0 0 0" />
      <geometry>
        <mesh filename="meshes/leg_3_upper.stl" scale="1 1 1" />
      </geometry>
    </collision>
  </link>
  <link name="leg_3_knee">
    <inertial>
      <origin xyz="0.000000000 0.000000000 0.000000000" rpy="0 0 0" />
      <mass value="0.098665260" />
      <inertia ixx="0.000038274" ixy="-0.000000000" ixz="0.000000000" iyy="0.000038274" iyz="-0.000000000" izz="0.000038274" />
    </inertial>
    <visual>
      <origin xyz="0 0 0" rpy="0 0 0" />
      <geometry>
        <mesh filename="meshes/leg_3_knee.stl" scale="1 1 1" />
      </geometry>
      <material name="joint_material">
        <color rgba="0.72 0.72 0.72 1.0" />
      </material>
    </visual>
    <collision>
      <origin xyz="0 0 0" rpy="0 0 0" />
      <geometry>
        <mesh filename="meshes/leg_3_knee.stl" scale="1 1 1" />
      </geometry>
    </collision>
  </link>
  <link name="leg_3_lower">
    <inertial>
      <origin xyz="-0.006502290 0.016307512 -0.148969075" rpy="0 0 0" />
      <mass value="0.200305203" />
      <inertia ixx="0.001513136" ixy="0.000007016" ixz="-0.000064087" iyy="0.001498339" iyz="0.000160728" izz="0.000047681" />
    </inertial>
    <visual>
      <origin xyz="0 0 0" rpy="0 0 0" />
      <geometry>
        <mesh filename="meshes/leg_3_lower.stl" scale="1 1 1" />
      </geometry>
      <material name="lower_link_material">
        <color rgba="0.11 0.60 0.44 1.0" />
      </material>
    </visual>
    <collision>
      <origin xyz="0 0 0" rpy="0 0 0" />
      <geometry>
        <mesh filename="meshes/leg_3_lower.stl" scale="1 1 1" />
      </geometry>
    </collision>
  </link>
  <link name="leg_3_foot">
    <inertial>
      <origin xyz="0.000000000 0.000000000 -0.000000000" rpy="0 0 0" />
      <mass value="0.057097951" />
      <inertia ixx="0.000015381" ixy="-0.000000000" ixz="-0.000000000" iyy="0.000015381" iyz="-0.000000000" izz="0.000015381" />
    </inertial>
    <visual>
      <origin xyz="0 0 0" rpy="0 0 0" />
      <geometry>
        <mesh filename="meshes/leg_3_foot.stl" scale="1 1 1" />
      </geometry>
      <material name="foot_material">
        <color rgba="0.90 0.52 0.14 1.0" />
      </material>
    </visual>
    <collision>
      <origin xyz="0 0 0" rpy="0 0 0" />
      <geometry>
        <mesh filename="meshes/leg_3_foot.stl" scale="1 1 1" />
      </geometry>
    </collision>
  </link>
  <link name="leg_4_hip">
    <inertial>
      <origin xyz="-0.000000000 0.000000000 0.000000000" rpy="0 0 0" />
      <mass value="0.135343292" />
      <inertia ixx="0.000064817" ixy="-0.000000000" ixz="0.000000000" iyy="0.000064817" iyz="0.000000000" izz="0.000064817" />
    </inertial>
    <visual>
      <origin xyz="0 0 0" rpy="0 0 0" />
      <geometry>
        <mesh filename="meshes/leg_4_hip.stl" scale="1 1 1" />
      </geometry>
      <material name="joint_material">
        <color rgba="0.72 0.72 0.72 1.0" />
      </material>
    </visual>
    <collision>
      <origin xyz="0 0 0" rpy="0 0 0" />
      <geometry>
        <mesh filename="meshes/leg_4_hip.stl" scale="1 1 1" />
      </geometry>
    </collision>
  </link>
  <link name="leg_4_swing_node">
    <inertial>
      <origin xyz="-0.000000000 0.000000000 -0.000000000" rpy="0 0 0" />
      <mass value="0.037168651" />
      <inertia ixx="0.000007521" ixy="0.000000000" ixz="-0.000000000" iyy="0.000007521" iyz="0.000000000" izz="0.000007521" />
    </inertial>
    <visual>
      <origin xyz="0 0 0" rpy="0 0 0" />
      <geometry>
        <mesh filename="meshes/leg_4_swing_node.stl" scale="1 1 1" />
      </geometry>
      <material name="joint_material">
        <color rgba="0.72 0.72 0.72 1.0" />
      </material>
    </visual>
    <collision>
      <origin xyz="0 0 0" rpy="0 0 0" />
      <geometry>
        <mesh filename="meshes/leg_4_swing_node.stl" scale="1 1 1" />
      </geometry>
    </collision>
  </link>
  <link name="leg_4_upper">
    <inertial>
      <origin xyz="-0.134024545 -0.035061977 -0.020200970" rpy="0 0 0" />
      <mass value="0.220878453" />
      <inertia ixx="0.000154625" ixy="-0.000341719" ixz="-0.000196882" iyy="0.001371452" iyz="-0.000051506" izz="0.001431174" />
    </inertial>
    <visual>
      <origin xyz="0 0 0" rpy="0 0 0" />
      <geometry>
        <mesh filename="meshes/leg_4_upper.stl" scale="1 1 1" />
      </geometry>
      <material name="upper_link_material">
        <color rgba="0.15 0.46 0.65 1.0" />
      </material>
    </visual>
    <collision>
      <origin xyz="0 0 0" rpy="0 0 0" />
      <geometry>
        <mesh filename="meshes/leg_4_upper.stl" scale="1 1 1" />
      </geometry>
    </collision>
  </link>
  <link name="leg_4_knee">
    <inertial>
      <origin xyz="0.000000000 0.000000000 0.000000000" rpy="0 0 0" />
      <mass value="0.098665260" />
      <inertia ixx="0.000038274" ixy="-0.000000000" ixz="0.000000000" iyy="0.000038274" iyz="-0.000000000" izz="0.000038274" />
    </inertial>
    <visual>
      <origin xyz="0 0 0" rpy="0 0 0" />
      <geometry>
        <mesh filename="meshes/leg_4_knee.stl" scale="1 1 1" />
      </geometry>
      <material name="joint_material">
        <color rgba="0.72 0.72 0.72 1.0" />
      </material>
    </visual>
    <collision>
      <origin xyz="0 0 0" rpy="0 0 0" />
      <geometry>
        <mesh filename="meshes/leg_4_knee.stl" scale="1 1 1" />
      </geometry>
    </collision>
  </link>
  <link name="leg_4_lower">
    <inertial>
      <origin xyz="-0.029161853 0.018427354 -0.145979516" rpy="0 0 0" />
      <mass value="0.200305203" />
      <inertia ixx="0.001459669" ixy="0.000035554" ixz="-0.000281654" iyy="0.001493467" iyz="0.000177977" izz="0.000106021" />
    </inertial>
    <visual>
      <origin xyz="0 0 0" rpy="0 0 0" />
      <geometry>
        <mesh filename="meshes/leg_4_lower.stl" scale="1 1 1" />
      </geometry>
      <material name="lower_link_material">
        <color rgba="0.11 0.60 0.44 1.0" />
      </material>
    </visual>
    <collision>
      <origin xyz="0 0 0" rpy="0 0 0" />
      <geometry>
        <mesh filename="meshes/leg_4_lower.stl" scale="1 1 1" />
      </geometry>
    </collision>
  </link>
  <link name="leg_4_foot">
    <inertial>
      <origin xyz="0.000000000 0.000000000 -0.000000000" rpy="0 0 0" />
      <mass value="0.057097951" />
      <inertia ixx="0.000015381" ixy="-0.000000000" ixz="-0.000000000" iyy="0.000015381" iyz="-0.000000000" izz="0.000015381" />
    </inertial>
    <visual>
      <origin xyz="0 0 0" rpy="0 0 0" />
      <geometry>
        <mesh filename="meshes/leg_4_foot.stl" scale="1 1 1" />
      </geometry>
      <material name="foot_material">
        <color rgba="0.90 0.52 0.14 1.0" />
      </material>
    </visual>
    <collision>
      <origin xyz="0 0 0" rpy="0 0 0" />
      <geometry>
        <mesh filename="meshes/leg_4_foot.stl" scale="1 1 1" />
      </geometry>
    </collision>
  </link>
  <link name="leg_5_hip">
    <inertial>
      <origin xyz="-0.000000000 0.000000000 0.000000000" rpy="0 0 0" />
      <mass value="0.135343292" />
      <inertia ixx="0.000064817" ixy="-0.000000000" ixz="0.000000000" iyy="0.000064817" iyz="0.000000000" izz="0.000064817" />
    </inertial>
    <visual>
      <origin xyz="0 0 0" rpy="0 0 0" />
      <geometry>
        <mesh filename="meshes/leg_5_hip.stl" scale="1 1 1" />
      </geometry>
      <material name="joint_material">
        <color rgba="0.72 0.72 0.72 1.0" />
      </material>
    </visual>
    <collision>
      <origin xyz="0 0 0" rpy="0 0 0" />
      <geometry>
        <mesh filename="meshes/leg_5_hip.stl" scale="1 1 1" />
      </geometry>
    </collision>
  </link>
  <link name="leg_5_swing_node">
    <inertial>
      <origin xyz="-0.000000000 0.000000000 -0.000000000" rpy="0 0 0" />
      <mass value="0.037168651" />
      <inertia ixx="0.000007521" ixy="0.000000000" ixz="-0.000000000" iyy="0.000007521" iyz="0.000000000" izz="0.000007521" />
    </inertial>
    <visual>
      <origin xyz="0 0 0" rpy="0 0 0" />
      <geometry>
        <mesh filename="meshes/leg_5_swing_node.stl" scale="1 1 1" />
      </geometry>
      <material name="joint_material">
        <color rgba="0.72 0.72 0.72 1.0" />
      </material>
    </visual>
    <collision>
      <origin xyz="0 0 0" rpy="0 0 0" />
      <geometry>
        <mesh filename="meshes/leg_5_swing_node.stl" scale="1 1 1" />
      </geometry>
    </collision>
  </link>
  <link name="leg_5_upper">
    <inertial>
      <origin xyz="-0.133434628 -0.037306993 -0.020084528" rpy="0 0 0" />
      <mass value="0.220878453" />
      <inertia ixx="0.000166099" ixy="-0.000361999" ixz="-0.000194885" iyy="0.001359638" iyz="-0.000054488" izz="0.001431515" />
    </inertial>
    <visual>
      <origin xyz="0 0 0" rpy="0 0 0" />
      <geometry>
        <mesh filename="meshes/leg_5_upper.stl" scale="1 1 1" />
      </geometry>
      <material name="upper_link_material">
        <color rgba="0.15 0.46 0.65 1.0" />
      </material>
    </visual>
    <collision>
      <origin xyz="0 0 0" rpy="0 0 0" />
      <geometry>
        <mesh filename="meshes/leg_5_upper.stl" scale="1 1 1" />
      </geometry>
    </collision>
  </link>
  <link name="leg_5_knee">
    <inertial>
      <origin xyz="0.000000000 0.000000000 0.000000000" rpy="0 0 0" />
      <mass value="0.098665260" />
      <inertia ixx="0.000038274" ixy="-0.000000000" ixz="0.000000000" iyy="0.000038274" iyz="-0.000000000" izz="0.000038274" />
    </inertial>
    <visual>
      <origin xyz="0 0 0" rpy="0 0 0" />
      <geometry>
        <mesh filename="meshes/leg_5_knee.stl" scale="1 1 1" />
      </geometry>
      <material name="joint_material">
        <color rgba="0.72 0.72 0.72 1.0" />
      </material>
    </visual>
    <collision>
      <origin xyz="0 0 0" rpy="0 0 0" />
      <geometry>
        <mesh filename="meshes/leg_5_knee.stl" scale="1 1 1" />
      </geometry>
    </collision>
  </link>
  <link name="leg_5_lower">
    <inertial>
      <origin xyz="-0.029198078 0.018052803 -0.146019069" rpy="0 0 0" />
      <mass value="0.200305203" />
      <inertia ixx="0.001459529" ixy="0.000034874" ixz="-0.000282080" iyy="0.001494371" iyz="0.000174406" izz="0.000105257" />
    </inertial>
    <visual>
      <origin xyz="0 0 0" rpy="0 0 0" />
      <geometry>
        <mesh filename="meshes/leg_5_lower.stl" scale="1 1 1" />
      </geometry>
      <material name="lower_link_material">
        <color rgba="0.11 0.60 0.44 1.0" />
      </material>
    </visual>
    <collision>
      <origin xyz="0 0 0" rpy="0 0 0" />
      <geometry>
        <mesh filename="meshes/leg_5_lower.stl" scale="1 1 1" />
      </geometry>
    </collision>
  </link>
  <link name="leg_5_foot">
    <inertial>
      <origin xyz="0.000000000 0.000000000 -0.000000000" rpy="0 0 0" />
      <mass value="0.057097951" />
      <inertia ixx="0.000015381" ixy="-0.000000000" ixz="-0.000000000" iyy="0.000015381" iyz="-0.000000000" izz="0.000015381" />
    </inertial>
    <visual>
      <origin xyz="0 0 0" rpy="0 0 0" />
      <geometry>
        <mesh filename="meshes/leg_5_foot.stl" scale="1 1 1" />
      </geometry>
      <material name="foot_material">
        <color rgba="0.90 0.52 0.14 1.0" />
      </material>
    </visual>
    <collision>
      <origin xyz="0 0 0" rpy="0 0 0" />
      <geometry>
        <mesh filename="meshes/leg_5_foot.stl" scale="1 1 1" />
      </geometry>
    </collision>
  </link>
  <link name="leg_6_hip">
    <inertial>
      <origin xyz="-0.000000000 0.000000000 0.000000000" rpy="0 0 0" />
      <mass value="0.135343292" />
      <inertia ixx="0.000064817" ixy="-0.000000000" ixz="0.000000000" iyy="0.000064817" iyz="0.000000000" izz="0.000064817" />
    </inertial>
    <visual>
      <origin xyz="0 0 0" rpy="0 0 0" />
      <geometry>
        <mesh filename="meshes/leg_6_hip.stl" scale="1 1 1" />
      </geometry>
      <material name="joint_material">
        <color rgba="0.72 0.72 0.72 1.0" />
      </material>
    </visual>
    <collision>
      <origin xyz="0 0 0" rpy="0 0 0" />
      <geometry>
        <mesh filename="meshes/leg_6_hip.stl" scale="1 1 1" />
      </geometry>
    </collision>
  </link>
  <link name="leg_6_swing_node">
    <inertial>
      <origin xyz="-0.000000000 0.000000000 -0.000000000" rpy="0 0 0" />
      <mass value="0.037168651" />
      <inertia ixx="0.000007521" ixy="0.000000000" ixz="-0.000000000" iyy="0.000007521" iyz="0.000000000" izz="0.000007521" />
    </inertial>
    <visual>
      <origin xyz="0 0 0" rpy="0 0 0" />
      <geometry>
        <mesh filename="meshes/leg_6_swing_node.stl" scale="1 1 1" />
      </geometry>
      <material name="joint_material">
        <color rgba="0.72 0.72 0.72 1.0" />
      </material>
    </visual>
    <collision>
      <origin xyz="0 0 0" rpy="0 0 0" />
      <geometry>
        <mesh filename="meshes/leg_6_swing_node.stl" scale="1 1 1" />
      </geometry>
    </collision>
  </link>
  <link name="leg_6_upper">
    <inertial>
      <origin xyz="-0.118770840 -0.071825750 -0.018290687" rpy="0 0 0" />
      <mass value="0.220878453" />
      <inertia ixx="0.000435035" ixy="-0.000620353" ixz="-0.000157975" iyy="0.001085695" iyz="-0.000095534" izz="0.001436521" />
    </inertial>
    <visual>
      <origin xyz="0 0 0" rpy="0 0 0" />
      <geometry>
        <mesh filename="meshes/leg_6_upper.stl" scale="1 1 1" />
      </geometry>
      <material name="upper_link_material">
        <color rgba="0.15 0.46 0.65 1.0" />
      </material>
    </visual>
    <collision>
      <origin xyz="0 0 0" rpy="0 0 0" />
      <geometry>
        <mesh filename="meshes/leg_6_upper.stl" scale="1 1 1" />
      </geometry>
    </collision>
  </link>
  <link name="leg_6_knee">
    <inertial>
      <origin xyz="0.000000000 0.000000000 0.000000000" rpy="0 0 0" />
      <mass value="0.098665260" />
      <inertia ixx="0.000038274" ixy="-0.000000000" ixz="0.000000000" iyy="0.000038274" iyz="-0.000000000" izz="0.000038274" />
    </inertial>
    <visual>
      <origin xyz="0 0 0" rpy="0 0 0" />
      <geometry>
        <mesh filename="meshes/leg_6_knee.stl" scale="1 1 1" />
      </geometry>
      <material name="joint_material">
        <color rgba="0.72 0.72 0.72 1.0" />
      </material>
    </visual>
    <collision>
      <origin xyz="0 0 0" rpy="0 0 0" />
      <geometry>
        <mesh filename="meshes/leg_6_knee.stl" scale="1 1 1" />
      </geometry>
    </collision>
  </link>
  <link name="leg_6_lower">
    <inertial>
      <origin xyz="-0.028870775 0.011663172 -0.146732576" rpy="0 0 0" />
      <mass value="0.200305203" />
      <inertia ixx="0.001460786" ixy="0.000022278" ixz="-0.000280281" iyy="0.001506934" iyz="0.000113227" izz="0.000091437" />
    </inertial>
    <visual>
      <origin xyz="0 0 0" rpy="0 0 0" />
      <geometry>
        <mesh filename="meshes/leg_6_lower.stl" scale="1 1 1" />
      </geometry>
      <material name="lower_link_material">
        <color rgba="0.11 0.60 0.44 1.0" />
      </material>
    </visual>
    <collision>
      <origin xyz="0 0 0" rpy="0 0 0" />
      <geometry>
        <mesh filename="meshes/leg_6_lower.stl" scale="1 1 1" />
      </geometry>
    </collision>
  </link>
  <link name="leg_6_foot">
    <inertial>
      <origin xyz="0.000000000 0.000000000 -0.000000000" rpy="0 0 0" />
      <mass value="0.057097951" />
      <inertia ixx="0.000015381" ixy="-0.000000000" ixz="-0.000000000" iyy="0.000015381" iyz="-0.000000000" izz="0.000015381" />
    </inertial>
    <visual>
      <origin xyz="0 0 0" rpy="0 0 0" />
      <geometry>
        <mesh filename="meshes/leg_6_foot.stl" scale="1 1 1" />
      </geometry>
      <material name="foot_material">
        <color rgba="0.90 0.52 0.14 1.0" />
      </material>
    </visual>
    <collision>
      <origin xyz="0 0 0" rpy="0 0 0" />
      <geometry>
        <mesh filename="meshes/leg_6_foot.stl" scale="1 1 1" />
      </geometry>
    </collision>
  </link>
  <link name="leg_7_hip">
    <inertial>
      <origin xyz="-0.000000000 0.000000000 0.000000000" rpy="0 0 0" />
      <mass value="0.135343292" />
      <inertia ixx="0.000064817" ixy="-0.000000000" ixz="0.000000000" iyy="0.000064817" iyz="0.000000000" izz="0.000064817" />
    </inertial>
    <visual>
      <origin xyz="0 0 0" rpy="0 0 0" />
      <geometry>
        <mesh filename="meshes/leg_7_hip.stl" scale="1 1 1" />
      </geometry>
      <material name="joint_material">
        <color rgba="0.72 0.72 0.72 1.0" />
      </material>
    </visual>
    <collision>
      <origin xyz="0 0 0" rpy="0 0 0" />
      <geometry>
        <mesh filename="meshes/leg_7_hip.stl" scale="1 1 1" />
      </geometry>
    </collision>
  </link>
  <link name="leg_7_swing_node">
    <inertial>
      <origin xyz="-0.000000000 0.000000000 -0.000000000" rpy="0 0 0" />
      <mass value="0.037168651" />
      <inertia ixx="0.000007521" ixy="0.000000000" ixz="-0.000000000" iyy="0.000007521" iyz="0.000000000" izz="0.000007521" />
    </inertial>
    <visual>
      <origin xyz="0 0 0" rpy="0 0 0" />
      <geometry>
        <mesh filename="meshes/leg_7_swing_node.stl" scale="1 1 1" />
      </geometry>
      <material name="joint_material">
        <color rgba="0.72 0.72 0.72 1.0" />
      </material>
    </visual>
    <collision>
      <origin xyz="0 0 0" rpy="0 0 0" />
      <geometry>
        <mesh filename="meshes/leg_7_swing_node.stl" scale="1 1 1" />
      </geometry>
    </collision>
  </link>
  <link name="leg_7_upper">
    <inertial>
      <origin xyz="-0.137266958 -0.020532822 -0.018335362" rpy="0 0 0" />
      <mass value="0.220878453" />
      <inertia ixx="0.000090658" ixy="-0.000204957" ixz="-0.000183023" iyy="0.001430191" iyz="-0.000027377" izz="0.001436402" />
    </inertial>
    <visual>
      <origin xyz="0 0 0" rpy="0 0 0" />
      <geometry>
        <mesh filename="meshes/leg_7_upper.stl" scale="1 1 1" />
      </geometry>
      <material name="upper_link_material">
        <color rgba="0.15 0.46 0.65 1.0" />
      </material>
    </visual>
    <collision>
      <origin xyz="0 0 0" rpy="0 0 0" />
      <geometry>
        <mesh filename="meshes/leg_7_upper.stl" scale="1 1 1" />
      </geometry>
    </collision>
  </link>
  <link name="leg_7_knee">
    <inertial>
      <origin xyz="0.000000000 0.000000000 0.000000000" rpy="0 0 0" />
      <mass value="0.098665260" />
      <inertia ixx="0.000038274" ixy="-0.000000000" ixz="0.000000000" iyy="0.000038274" iyz="-0.000000000" izz="0.000038274" />
    </inertial>
    <visual>
      <origin xyz="0 0 0" rpy="0 0 0" />
      <geometry>
        <mesh filename="meshes/leg_7_knee.stl" scale="1 1 1" />
      </geometry>
      <material name="joint_material">
        <color rgba="0.72 0.72 0.72 1.0" />
      </material>
    </visual>
    <collision>
      <origin xyz="0 0 0" rpy="0 0 0" />
      <geometry>
        <mesh filename="meshes/leg_7_knee.stl" scale="1 1 1" />
      </geometry>
    </collision>
  </link>
  <link name="leg_7_lower">
    <inertial>
      <origin xyz="-0.014888589 -0.027457156 -0.146712080" rpy="0 0 0" />
      <mass value="0.200305203" />
      <inertia ixx="0.001501268" ixy="-0.000027047" ixz="-0.000144520" iyy="0.001466054" iyz="-0.000266520" izz="0.000091835" />
    </inertial>
    <visual>
      <origin xyz="0 0 0" rpy="0 0 0" />
      <geometry>
        <mesh filename="meshes/leg_7_lower.stl" scale="1 1 1" />
      </geometry>
      <material name="lower_link_material">
        <color rgba="0.11 0.60 0.44 1.0" />
      </material>
    </visual>
    <collision>
      <origin xyz="0 0 0" rpy="0 0 0" />
      <geometry>
        <mesh filename="meshes/leg_7_lower.stl" scale="1 1 1" />
      </geometry>
    </collision>
  </link>
  <link name="leg_7_foot">
    <inertial>
      <origin xyz="0.000000000 0.000000000 -0.000000000" rpy="0 0 0" />
      <mass value="0.057097951" />
      <inertia ixx="0.000015381" ixy="-0.000000000" ixz="-0.000000000" iyy="0.000015381" iyz="-0.000000000" izz="0.000015381" />
    </inertial>
    <visual>
      <origin xyz="0 0 0" rpy="0 0 0" />
      <geometry>
        <mesh filename="meshes/leg_7_foot.stl" scale="1 1 1" />
      </geometry>
      <material name="foot_material">
        <color rgba="0.90 0.52 0.14 1.0" />
      </material>
    </visual>
    <collision>
      <origin xyz="0 0 0" rpy="0 0 0" />
      <geometry>
        <mesh filename="meshes/leg_7_foot.stl" scale="1 1 1" />
      </geometry>
    </collision>
  </link>
  <joint name="leg_0_mount" type="fixed">
    <parent link="base_link" />
    <child link="leg_0_hip" />
    <origin xyz="0.115208324 -0.252166135 -0.090000000" rpy="0.000000000 0.000000000 0.000000000" />
  </joint>
  <joint name="leg_0_lift" type="revolute">
    <parent link="leg_0_hip" />
    <child link="leg_0_swing_node" />
    <origin xyz="0.000000000 0.000000000 0.000000000" rpy="0.000000000 0.000000000 0.000000000" />
    <axis xyz="0.789875134 0.613267700 0.000000000" />
    <limit lower="-0.800000000" upper="0.950000000" effort="25.000000000" velocity="2.500000000" />
    <dynamics damping="0.200000000" friction="0.050000000" />
  </joint>
  <joint name="leg_0_swing" type="revolute">
    <parent link="leg_0_swing_node" />
    <child link="leg_0_upper" />
    <origin xyz="0.000000000 0.000000000 0.000000000" rpy="0.000000000 0.000000000 0.000000000" />
    <axis xyz="0.000000000 0.000000000 1.000000000" />
    <limit lower="-0.550000000" upper="0.550000000" effort="20.000000000" velocity="2.000000000" />
    <dynamics damping="0.150000000" friction="0.040000000" />
  </joint>
  <joint name="leg_0_knee_mount" type="fixed">
    <parent link="leg_0_upper" />
    <child link="leg_0_knee" />
    <origin xyz="0.005686805 -0.278118381 -0.031903393" rpy="0.000000000 0.000000000 0.000000000" />
  </joint>
  <joint name="leg_0_drop" type="revolute">
    <parent link="leg_0_knee" />
    <child link="leg_0_lower" />
    <origin xyz="0.000000000 0.000000000 0.000000000" rpy="0.000000000 0.000000000 0.000000000" />
    <axis xyz="0.789875134 0.613267700 0.000000000" />
    <limit lower="-0.100000000" upper="1.100000000" effort="18.000000000" velocity="2.300000000" />
    <dynamics damping="0.120000000" friction="0.030000000" />
  </joint>
  <joint name="leg_0_foot_mount" type="fixed">
    <parent link="leg_0_lower" />
    <child link="leg_0_foot" />
    <origin xyz="0.041672985 -0.023595685 -0.296153011" rpy="0.000000000 0.000000000 0.000000000" />
  </joint>
  <joint name="leg_1_mount" type="fixed">
    <parent link="base_link" />
    <child link="leg_1_hip" />
    <origin xyz="0.259942467 0.216558427 -0.090000000" rpy="0.000000000 0.000000000 0.000000000" />
  </joint>
  <joint name="leg_1_lift" type="revolute">
    <parent link="leg_1_hip" />
    <child link="leg_1_swing_node" />
    <origin xyz="0.000000000 0.000000000 0.000000000" rpy="0.000000000 0.000000000 0.000000000" />
    <axis xyz="-0.411068534 0.911604443 0.000000000" />
    <limit lower="-0.800000000" upper="0.950000000" effort="25.000000000" velocity="2.500000000" />
    <dynamics damping="0.200000000" friction="0.050000000" />
  </joint>
  <joint name="leg_1_swing" type="revolute">
    <parent link="leg_1_swing_node" />
    <child link="leg_1_upper" />
    <origin xyz="0.000000000 0.000000000 0.000000000" rpy="0.000000000 0.000000000 0.000000000" />
    <axis xyz="0.000000000 0.000000000 1.000000000" />
    <limit lower="-0.550000000" upper="0.550000000" effort="20.000000000" velocity="2.000000000" />
    <dynamics damping="0.150000000" friction="0.040000000" />
  </joint>
  <joint name="leg_1_knee_mount" type="fixed">
    <parent link="leg_1_upper" />
    <child link="leg_1_knee" />
    <origin xyz="0.131331517 0.245240502 -0.031766786" rpy="0.000000000 0.000000000 0.000000000" />
  </joint>
  <joint name="leg_1_drop" type="revolute">
    <parent link="leg_1_knee" />
    <child link="leg_1_lower" />
    <origin xyz="0.000000000 0.000000000 0.000000000" rpy="0.000000000 0.000000000 0.000000000" />
    <axis xyz="-0.411068534 0.911604443 0.000000000" />
    <limit lower="-0.100000000" upper="1.100000000" effort="18.000000000" velocity="2.300000000" />
    <dynamics damping="0.120000000" friction="0.030000000" />
  </joint>
  <joint name="leg_1_foot_mount" type="fixed">
    <parent link="leg_1_lower" />
    <child link="leg_1_foot" />
    <origin xyz="0.047236951 0.001979701 -0.296251162" rpy="0.000000000 0.000000000 0.000000000" />
  </joint>
  <joint name="leg_2_mount" type="fixed">
    <parent link="base_link" />
    <child link="leg_2_hip" />
    <origin xyz="0.238331579 0.264483722 -0.090000000" rpy="0.000000000 0.000000000 0.000000000" />
  </joint>
  <joint name="leg_2_lift" type="revolute">
    <parent link="leg_2_hip" />
    <child link="leg_2_swing_node" />
    <origin xyz="0.000000000 0.000000000 0.000000000" rpy="0.000000000 0.000000000 0.000000000" />
    <axis xyz="-0.411068534 0.911604443 0.000000000" />
    <limit lower="-0.800000000" upper="0.950000000" effort="25.000000000" velocity="2.500000000" />
    <dynamics damping="0.200000000" friction="0.050000000" />
  </joint>
  <joint name="leg_2_swing" type="revolute">
    <parent link="leg_2_swing_node" />
    <child link="leg_2_upper" />
    <origin xyz="0.000000000 0.000000000 0.000000000" rpy="0.000000000 0.000000000 0.000000000" />
    <axis xyz="0.000000000 0.000000000 1.000000000" />
    <limit lower="-0.550000000" upper="0.550000000" effort="20.000000000" velocity="2.000000000" />
    <dynamics damping="0.150000000" friction="0.040000000" />
  </joint>
  <joint name="leg_2_knee_mount" type="fixed">
    <parent link="leg_2_upper" />
    <child link="leg_2_knee" />
    <origin xyz="0.224788506 0.161576310 -0.041990757" rpy="0.000000000 0.000000000 0.000000000" />
  </joint>
  <joint name="leg_2_drop" type="revolute">
    <parent link="leg_2_knee" />
    <child link="leg_2_lower" />
    <origin xyz="0.000000000 0.000000000 0.000000000" rpy="0.000000000 0.000000000 0.000000000" />
    <axis xyz="-0.411068534 0.911604443 0.000000000" />
    <limit lower="-0.100000000" upper="1.100000000" effort="18.000000000" velocity="2.300000000" />
    <dynamics damping="0.120000000" friction="0.030000000" />
  </joint>
  <joint name="leg_2_foot_mount" type="fixed">
    <parent link="leg_2_lower" />
    <child link="leg_2_foot" />
    <origin xyz="0.012518463 0.069978466 -0.291455490" rpy="0.000000000 0.000000000 0.000000000" />
  </joint>
  <joint name="leg_3_mount" type="fixed">
    <parent link="base_link" />
    <child link="leg_3_hip" />
    <origin xyz="0.183386223 0.268544448 -0.090000000" rpy="0.000000000 0.000000000 0.000000000" />
  </joint>
  <joint name="leg_3_lift" type="revolute">
    <parent link="leg_3_hip" />
    <child link="leg_3_swing_node" />
    <origin xyz="0.000000000 0.000000000 0.000000000" rpy="0.000000000 0.000000000 0.000000000" />
    <axis xyz="-0.959884293 -0.280396404 0.000000000" />
    <limit lower="-0.800000000" upper="0.950000000" effort="25.000000000" velocity="2.500000000" />
    <dynamics damping="0.200000000" friction="0.050000000" />
  </joint>
  <joint name="leg_3_swing" type="revolute">
    <parent link="leg_3_swing_node" />
    <child link="leg_3_upper" />
    <origin xyz="0.000000000 0.000000000 0.000000000" rpy="0.000000000 0.000000000 0.000000000" />
    <axis xyz="0.000000000 0.000000000 1.000000000" />
    <limit lower="-0.550000000" upper="0.550000000" effort="20.000000000" velocity="2.000000000" />
    <dynamics damping="0.150000000" friction="0.040000000" />
  </joint>
  <joint name="leg_3_knee_mount" type="fixed">
    <parent link="leg_3_upper" />
    <child link="leg_3_knee" />
    <origin xyz="0.170750294 0.219916874 -0.029680052" rpy="0.000000000 0.000000000 0.000000000" />
  </joint>
  <joint name="leg_3_drop" type="revolute">
    <parent link="leg_3_knee" />
    <child link="leg_3_lower" />
    <origin xyz="0.000000000 0.000000000 0.000000000" rpy="0.000000000 0.000000000 0.000000000" />
    <axis xyz="-0.959884293 -0.280396404 0.000000000" />
    <limit lower="-0.100000000" upper="1.100000000" effort="18.000000000" velocity="2.300000000" />
    <dynamics damping="0.120000000" friction="0.030000000" />
  </joint>
  <joint name="leg_3_foot_mount" type="fixed">
    <parent link="leg_3_lower" />
    <child link="leg_3_foot" />
    <origin xyz="-0.013004581 0.032615023 -0.297938150" rpy="0.000000000 0.000000000 0.000000000" />
  </joint>
  <joint name="leg_4_mount" type="fixed">
    <parent link="base_link" />
    <child link="leg_4_hip" />
    <origin xyz="-0.239859929 0.011547865 -0.090000000" rpy="0.000000000 0.000000000 0.000000000" />
  </joint>
  <joint name="leg_4_lift" type="revolute">
    <parent link="leg_4_hip" />
    <child link="leg_4_swing_node" />
    <origin xyz="0.000000000 0.000000000 0.000000000" rpy="0.000000000 0.000000000 0.000000000" />
    <axis xyz="0.335939219 -0.941883667 0.000000000" />
    <limit lower="-0.800000000" upper="0.950000000" effort="25.000000000" velocity="2.500000000" />
    <dynamics damping="0.200000000" friction="0.050000000" />
  </joint>
  <joint name="leg_4_swing" type="revolute">
    <parent link="leg_4_swing_node" />
    <child link="leg_4_upper" />
    <origin xyz="0.000000000 0.000000000 0.000000000" rpy="0.000000000 0.000000000 0.000000000" />
    <axis xyz="0.000000000 0.000000000 1.000000000" />
    <limit lower="-0.550000000" upper="0.550000000" effort="20.000000000" velocity="2.000000000" />
    <dynamics damping="0.150000000" friction="0.040000000" />
  </joint>
  <joint name="leg_4_knee_mount" type="fixed">
    <parent link="leg_4_upper" />
    <child link="leg_4_knee" />
    <origin xyz="-0.268049090 -0.070123954 -0.040401939" rpy="0.000000000 0.000000000 0.000000000" />
  </joint>
  <joint name="leg_4_drop" type="revolute">
    <parent link="leg_4_knee" />
    <child link="leg_4_lower" />
    <origin xyz="0.000000000 0.000000000 0.000000000" rpy="0.000000000 0.000000000 0.000000000" />
    <axis xyz="0.335939219 -0.941883667 0.000000000" />
    <limit lower="-0.100000000" upper="1.100000000" effort="18.000000000" velocity="2.300000000" />
    <dynamics damping="0.120000000" friction="0.030000000" />
  </joint>
  <joint name="leg_4_foot_mount" type="fixed">
    <parent link="leg_4_lower" />
    <child link="leg_4_foot" />
    <origin xyz="-0.058323705 0.036854707 -0.291959031" rpy="0.000000000 0.000000000 0.000000000" />
  </joint>
  <joint name="leg_5_mount" type="fixed">
    <parent link="base_link" />
    <child link="leg_5_hip" />
    <origin xyz="-0.238165856 0.006798139 -0.090000000" rpy="0.000000000 0.000000000 0.000000000" />
  </joint>
  <joint name="leg_5_lift" type="revolute">
    <parent link="leg_5_hip" />
    <child link="leg_5_swing_node" />
    <origin xyz="0.000000000 0.000000000 0.000000000" rpy="0.000000000 0.000000000 0.000000000" />
    <axis xyz="0.335939219 -0.941883667 0.000000000" />
    <limit lower="-0.800000000" upper="0.950000000" effort="25.000000000" velocity="2.500000000" />
    <dynamics damping="0.200000000" friction="0.050000000" />
  </joint>
  <joint name="leg_5_swing" type="revolute">
    <parent link="leg_5_swing_node" />
    <child link="leg_5_upper" />
    <origin xyz="0.000000000 0.000000000 0.000000000" rpy="0.000000000 0.000000000 0.000000000" />
    <axis xyz="0.000000000 0.000000000 1.000000000" />
    <limit lower="-0.550000000" upper="0.550000000" effort="20.000000000" velocity="2.000000000" />
    <dynamics damping="0.150000000" friction="0.040000000" />
  </joint>
  <joint name="leg_5_knee_mount" type="fixed">
    <parent link="leg_5_upper" />
    <child link="leg_5_knee" />
    <origin xyz="-0.266869256 -0.074613987 -0.040169056" rpy="0.000000000 0.000000000 0.000000000" />
  </joint>
  <joint name="leg_5_drop" type="revolute">
    <parent link="leg_5_knee" />
    <child link="leg_5_lower" />
    <origin xyz="0.000000000 0.000000000 0.000000000" rpy="0.000000000 0.000000000 0.000000000" />
    <axis xyz="0.335939219 -0.941883667 0.000000000" />
    <limit lower="-0.100000000" upper="1.100000000" effort="18.000000000" velocity="2.300000000" />
    <dynamics damping="0.120000000" friction="0.030000000" />
  </joint>
  <joint name="leg_5_foot_mount" type="fixed">
    <parent link="leg_5_lower" />
    <child link="leg_5_foot" />
    <origin xyz="-0.058396156 0.036105606 -0.292038138" rpy="0.000000000 0.000000000 0.000000000" />
  </joint>
  <joint name="leg_6_mount" type="fixed">
    <parent link="base_link" />
    <child link="leg_6_hip" />
    <origin xyz="-0.211984730 -0.066606732 -0.090000000" rpy="0.000000000 0.000000000 0.000000000" />
  </joint>
  <joint name="leg_6_lift" type="revolute">
    <parent link="leg_6_hip" />
    <child link="leg_6_swing_node" />
    <origin xyz="0.000000000 0.000000000 0.000000000" rpy="0.000000000 0.000000000 0.000000000" />
    <axis xyz="0.335939219 -0.941883667 0.000000000" />
    <limit lower="-0.800000000" upper="0.950000000" effort="25.000000000" velocity="2.500000000" />
    <dynamics damping="0.200000000" friction="0.050000000" />
  </joint>
  <joint name="leg_6_swing" type="revolute">
    <parent link="leg_6_swing_node" />
    <child link="leg_6_upper" />
    <origin xyz="0.000000000 0.000000000 0.000000000" rpy="0.000000000 0.000000000 0.000000000" />
    <axis xyz="0.000000000 0.000000000 1.000000000" />
    <limit lower="-0.550000000" upper="0.550000000" effort="20.000000000" velocity="2.000000000" />
    <dynamics damping="0.150000000" friction="0.040000000" />
  </joint>
  <joint name="leg_6_knee_mount" type="fixed">
    <parent link="leg_6_upper" />
    <child link="leg_6_knee" />
    <origin xyz="-0.237541679 -0.143651501 -0.036581373" rpy="0.000000000 0.000000000 0.000000000" />
  </joint>
  <joint name="leg_6_drop" type="revolute">
    <parent link="leg_6_knee" />
    <child link="leg_6_lower" />
    <origin xyz="0.000000000 0.000000000 0.000000000" rpy="0.000000000 0.000000000 0.000000000" />
    <axis xyz="0.335939219 -0.941883667 0.000000000" />
    <limit lower="-0.100000000" upper="1.100000000" effort="18.000000000" velocity="2.300000000" />
    <dynamics damping="0.120000000" friction="0.030000000" />
  </joint>
  <joint name="leg_6_foot_mount" type="fixed">
    <parent link="leg_6_lower" />
    <child link="leg_6_foot" />
    <origin xyz="-0.057741550 0.023326344 -0.293465151" rpy="0.000000000 0.000000000 0.000000000" />
  </joint>
  <joint name="leg_7_mount" type="fixed">
    <parent link="base_link" />
    <child link="leg_7_hip" />
    <origin xyz="-0.188328386 -0.132932790 -0.090000000" rpy="0.000000000 0.000000000 0.000000000" />
  </joint>
  <joint name="leg_7_lift" type="revolute">
    <parent link="leg_7_hip" />
    <child link="leg_7_swing_node" />
    <origin xyz="0.000000000 0.000000000 0.000000000" rpy="0.000000000 0.000000000 0.000000000" />
    <axis xyz="0.335939219 -0.941883667 0.000000000" />
    <limit lower="-0.800000000" upper="0.950000000" effort="25.000000000" velocity="2.500000000" />
    <dynamics damping="0.200000000" friction="0.050000000" />
  </joint>
  <joint name="leg_7_swing" type="revolute">
    <parent link="leg_7_swing_node" />
    <child link="leg_7_upper" />
    <origin xyz="0.000000000 0.000000000 0.000000000" rpy="0.000000000 0.000000000 0.000000000" />
    <axis xyz="0.000000000 0.000000000 1.000000000" />
    <limit lower="-0.550000000" upper="0.550000000" effort="20.000000000" velocity="2.000000000" />
    <dynamics damping="0.150000000" friction="0.040000000" />
  </joint>
  <joint name="leg_7_knee_mount" type="fixed">
    <parent link="leg_7_upper" />
    <child link="leg_7_knee" />
    <origin xyz="-0.274533916 -0.041065644 -0.036670725" rpy="0.000000000 0.000000000 0.000000000" />
  </joint>
  <joint name="leg_7_drop" type="revolute">
    <parent link="leg_7_knee" />
    <child link="leg_7_lower" />
    <origin xyz="0.000000000 0.000000000 0.000000000" rpy="0.000000000 0.000000000 0.000000000" />
    <axis xyz="0.335939219 -0.941883667 0.000000000" />
    <limit lower="-0.100000000" upper="1.100000000" effort="18.000000000" velocity="2.300000000" />
    <dynamics damping="0.120000000" friction="0.030000000" />
  </joint>
  <joint name="leg_7_foot_mount" type="fixed">
    <parent link="leg_7_lower" />
    <child link="leg_7_foot" />
    <origin xyz="-0.029777178 -0.054914311 -0.293424161" rpy="0.000000000 0.000000000 0.000000000" />
  </joint>
</robot>